<robot xmlns:xacro="http://www.ros.org/wiki/xacro"
xmlns:sensor="http://playerstage.sourceforge.net/gazebo/xmlschema/#sensor"
xmlns:controller="http://playerstage.sourceforge.net/gazebo/xmlschema/#controller"
xmlns:joint="http://playerstage.sourceforge.net/gazebo/xmlschema/#slider"
xmlns:interface="http://playerstage.sourceforge.net/gazebo/xmlschema/#interface"
xmlns:body="http://playerstage.sourceforge.net/gazebo/xmlschema/#body"
xmlns:geom="http://playerstage.sourceforge.net/gazebo/xmlschema/#geom">

  <xacro:include filename="$(find sr_description)/hand/xacro/finger/proximal/proximal.gazebo.xacro" />
  <xacro:include filename="$(find sr_description)/hand/xacro/finger/proximal/proximal.transmission.xacro" />
  <!-- muscle is true for muscle hand or false for motor hand -->
  <!-- prefix can be anything but usually is "r_" or  "l_" for right and left hands distinction -->
  <!-- link_prefix prepends fingername to the link names -->
  <!-- joint_prefix prepends fingername to the joint names -->
  <!-- parent is the parent link for the joint -->
  <xacro:macro name="proximal"
  params="muscle prefix link_prefix joint_prefix parent">
    <link name="${prefix}${link_prefix}proximal">
      <inertial>
        <mass value="0.030" />
        <origin xyz="0 0 0.0225" />
        <inertia ixx="0.0000098" ixy="0.0" ixz="0.0" iyy="0.00001"
        iyz="0.0" izz="0.0000018" />
      </inertial>
      <visual>
        <origin xyz="0 0 0" rpy="0 0 0" />
        <geometry name="${prefix}${link_prefix}proximal_visual">
          <mesh filename="package://sr_description/meshes/hand/F3.dae"
          scale="0.001 0.001 0.001" />
        </geometry>
        <material name="Grey" />
      </visual>
      <collision>
        <origin xyz="0 0 0.025" rpy="0 0 0" />
        <geometry name="${prefix}${link_prefix}proximal_collision_geom">

          <cylinder radius="0.007" length="0.040" />
        </geometry>
      </collision>
    </link>
    <joint name="${prefix}${joint_prefix}J3" type="revolute">
      <parent link="${parent}" />
      <child link="${prefix}${link_prefix}proximal" />
      <origin xyz="0 0 0" rpy="0 0 0" />
      <axis xyz="1 0 0" />
      <limit lower="-${15.0*M_PI/180}" upper="${M_PI/2}" effort="2"
      velocity="2.0" />
      <dynamics damping="0.1" />
    </joint>
    <gazebo reference="${prefix}${joint_prefix}J3">
      <provideFeedback>1</provideFeedback>
      <implicitSpringDamper>1</implicitSpringDamper>
    </gazebo>
    <!-- extensions -->
    <xacro:proximal_transmission muscletrans="${muscle}"
    prefix="${prefix}" joint_prefix="${joint_prefix}"
    link_prefix="${link_prefix}" />
    <xacro:proximal_gazebo prefix="${prefix}"
    link_prefix="${link_prefix}" />
  </xacro:macro>
</robot>
