<robot xmlns:xacro="http://www.ros.org/wiki/xacro"
xmlns:sensor="http://playerstage.sourceforge.net/gazebo/xmlschema/#sensor"
xmlns:controller="http://playerstage.sourceforge.net/gazebo/xmlschema/#controller"
xmlns:joint="http://playerstage.sourceforge.net/gazebo/xmlschema/#slider"
xmlns:interface="http://playerstage.sourceforge.net/gazebo/xmlschema/#interface"
xmlns:body="http://playerstage.sourceforge.net/gazebo/xmlschema/#body"
xmlns:geom="http://playerstage.sourceforge.net/gazebo/xmlschema/#geom">

  <xacro:include filename="$(find sr_description)/hand/xacro/finger/distal/distal.gazebo.xacro" />
  <xacro:include filename="$(find sr_description)/hand/xacro/finger/distal/distal.transmission.xacro" />
  <!-- muscle is true for muscle hand or false for motor hand -->
  <!-- bio is true for biotac finger or false for standard finger -->
  <!-- bt_sp is true for BT_SP finger or false for standard finger -->
  <!-- ubi is true for ubi finger or false for standard finger -->
  <!-- eli is true for ellipsoid fingertip or false for standard finger -->
  <!-- prefix can be anything but usually is "r_" or  "l_" for right and left hands distinction -->
  <!-- link_prefix prepends fingername to the link names -->
  <!-- joint_prefix prepends fingername to the joint names -->
  <!-- parent is the parent link for the joint -->
  <xacro:macro name="distal"
  params="muscle bio bt_sp ubi eli prefix link_prefix joint_prefix parent">

    <link name="${prefix}${link_prefix}distal">
      <inertial>
        <mass value="0.012" />
        <origin xyz="0 0 0.012" />
        <inertia ixx="0.00000094" ixy="0.0" ixz="0.0"
		 iyy="0.0000011" iyz="0.0" izz="0.00000053" />
      </inertial>
      <visual>
        <origin xyz="0 0 0" rpy="0 0 0" />
        <geometry name="${prefix}${link_prefix}distal_visual">
          <xacro:if value="${ubi}">
            <!-- Ubi distal -->
            <mesh filename="package://sr_description/meshes/hand/ubi_tactiles/ubi_tip_visual.dae"
		  scale="0.001 0.001 0.001" />
          </xacro:if>
          <xacro:unless value="${ubi}">
            <xacro:if value="${eli}">
              <!-- Ellispoid distal  -->
              <mesh filename="package://sr_description/meshes/hand/ellipsoids/distal_ellipsoid_visual.dae"
		    scale="0.001 0.001 0.001" />
            </xacro:if>
            <xacro:unless value="${eli}">
              <xacro:if value="${bio}">
                <!-- biotac distal  -->
                <mesh filename="package://sr_description/meshes/hand/F1.dae"
                      scale="0.001 0.001 0.001" />
              </xacro:if>
              <xacro:unless value="${bio}">
		<xacro:if value="${bt_sp}">
                  <!-- bt_sp distal  -->
                  <mesh filename="package://sr_description/meshes/hand/biotacs/sp.dae" />
		</xacro:if>
		<xacro:unless value="${bt_sp}">
                  <!-- Standard distal  -->
                  <mesh filename="package://sr_description/meshes/hand/F1.dae"
			scale="0.001 0.001 0.001" />
		</xacro:unless>
              </xacro:unless>
            </xacro:unless>
          </xacro:unless>
        </geometry>
        <!-- <material name="Grey" /> -->
      </visual>
      <collision>
        <origin xyz="0 0 0" rpy="0 0 0" />
        <geometry name="${prefix}${link_prefix}distal_collision_geom">

          <xacro:if value="${ubi}">
            <!-- Ubi distal -->
            <mesh filename="package://sr_description/meshes/hand/ubi_tactiles/ubi_tip_collision.dae"
            scale="0.001 0.001 0.001" />
          </xacro:if>
          <xacro:unless value="${ubi}">
            <xacro:if value="${eli}">
              <!-- Ellispoid distal  -->
              <mesh filename="package://sr_description/meshes/hand/ellipsoids/distal_ellipsoid.dae"
              scale="0.001 0.001 0.001" />
            </xacro:if>
            <xacro:unless value="${eli}">
              <xacro:if value="${bio}">
                <!-- biotac distal  -->
                <mesh filename="package://sr_description/meshes/hand/F1.dae"
                scale="0.001 0.001 0.001" />
              </xacro:if>
              <xacro:unless value="${bio}">
		<xacro:if value="${bt_sp}">
                  <!-- bt_sp distal  -->
                  <mesh filename="package://sr_description/meshes/hand/biotacs/sp.dae" />
		</xacro:if>
		<xacro:unless value="${bt_sp}">
                  <!-- Standard distal  -->
                  <mesh filename="package://sr_description/meshes/hand/F1.dae"
			scale="0.001 0.001 0.001" />
		</xacro:unless>
              </xacro:unless>
            </xacro:unless>
          </xacro:unless>
        </geometry>
      </collision>
    </link>
    <xacro:unless value="${bio}">
      <joint name="${prefix}${joint_prefix}J1" type="revolute">
        <parent link="${parent}" />
        <child link="${prefix}${link_prefix}distal" />
        <origin xyz="0 0 0.025" rpy="0 0 0" />
        <axis xyz="1 0 0" />
        <xacro:if value="${bio}">
          <!-- biotac fixed distal joint -->
          <limit lower="${20/180*M_PI}" upper="${20/180*M_PI}"
          effort="10" velocity="2.0" />
        </xacro:if>
        <xacro:unless value="${bio}">
          <!-- standard distal joint -->
          <limit lower="0" upper="${M_PI/2}" effort="2"
          velocity="2.0" />
        </xacro:unless>
        <dynamics damping="0.1" />
      </joint>
      <gazebo reference="${prefix}${joint_prefix}J1">
        <provideFeedback>1</provideFeedback>
        <implicitSpringDamper>1</implicitSpringDamper>
      </gazebo>
      <link name="${prefix}${link_prefix}tip">
        <inertial>
          <mass value="0.001" />
          <inertia ixx="0.0" ixy="0.0" ixz="0.0" iyy="0.0"
          iyz="0.0" izz="0.0" />
        </inertial>
      </link>
      <joint name="${prefix}${joint_prefix}tip" type="fixed">
        <parent link="${prefix}${link_prefix}distal" />
        <child link="${prefix}${link_prefix}tip" />
        <origin xyz="0 0 0.026" rpy="0 0 0" />
      </joint>
    </xacro:unless>
    <!-- extensions -->
    <xacro:distal_gazebo prefix="${prefix}"
    link_prefix="${link_prefix}" />
  </xacro:macro>
</robot>
