<robot xmlns:xacro="http://www.ros.org/wiki/xacro"
xmlns:sensor="http://playerstage.sourceforge.net/gazebo/xmlschema/#sensor"
xmlns:controller="http://playerstage.sourceforge.net/gazebo/xmlschema/#controller"
xmlns:joint="http://playerstage.sourceforge.net/gazebo/xmlschema/#slider"
xmlns:interface="http://playerstage.sourceforge.net/gazebo/xmlschema/#interface"
xmlns:body="http://playerstage.sourceforge.net/gazebo/xmlschema/#body"
xmlns:geom="http://playerstage.sourceforge.net/gazebo/xmlschema/#geom">

  <xacro:include filename="$(find sr_description)/hand/xacro/finger/middle/middle.transmission.xacro" />
  <!-- muscle is true for muscle hand or false for motor hand -->
  <!-- prefix can be anything but usually is "r_" or  "l_" for right and left hands distinction -->
  <!-- link_prefix prepends fingername to the link names -->
  <!-- joint_prefix prepends fingername to the joint names -->
  <!-- parent is the parent link for the joint -->
  <xacro:macro name="biotac_middle"
  params="muscle prefix link_prefix joint_prefix parent">
    <link name="${prefix}${link_prefix}middle">
      <inertial>
        <origin xyz="0 0 0.0125" rpy="0 0 0" />
        <mass value="0.017" />
        <inertia ixx="0.0000026" ixy="0.0" ixz="0.0"
        iyy="0.0000027" iyz="0.0" izz="0.00000087" />
      </inertial>
      <visual>
        <origin xyz="0 0 0" rpy="0 0 1.571" />
        <geometry name="${prefix}${link_prefix}middle_visual">
          <mesh filename="package://sr_description/meshes/hand/biotacs/biotac_finger_adapter.dae"
          scale="1 1 1" />
        </geometry>
        <material name="LightGrey" />
      </visual>
      <collision>
        <origin xyz="0 0 0.005" rpy="0 0 0" />
        <geometry name="${prefix}${link_prefix}middle_collision_geom">

          <box size="0.001 0.001 0.001" />
        </geometry>
      </collision>
    </link>
    <gazebo reference="${prefix}${link_prefix}middle">
      <sensor type="contact"
      name="${prefix}${link_prefix}middle_contact">
        <always_on>1</always_on>
        <update_rate>1000.0</update_rate>
        <contact>
          <collision>
          ${prefix}${link_prefix}middle_collision</collision>
          <topic>${prefix}${link_prefix}middle_collision</topic>
        </contact>
        <plugin name="${prefix}${link_prefix}middle_gazebo_ros_bumper_controller"
        filename="libgazebo_ros_bumper.so">
          <updateRate>100.0</updateRate>
          <frameName>${prefix}${link_prefix}middle</frameName>
          <bumperTopicName>
          contacts/${prefix}${link_prefix}/middle</bumperTopicName>
        </plugin>
      </sensor>
      <material>Gazebo/FlatBlack</material>
    </gazebo>
    <joint name="${prefix}${joint_prefix}J2" type="revolute">
      <parent link="${parent}" />
      <child link="${prefix}${link_prefix}middle" />
      <origin xyz="0 0 0.045" rpy="0 0 0" />
      <axis xyz="1 0 0" />
      <limit lower="0" upper="${M_PI/2}" effort="2.0"
      velocity="2.0" />
      <dynamics damping="0.1" />
    </joint>
    <gazebo reference="${prefix}${joint_prefix}J2">
      <provideFeedback>1</provideFeedback>
      <implicitSpringDamper>1</implicitSpringDamper>
    </gazebo>
    <link name="${prefix}${link_prefix}_J1_dummy">
      <inertial>
        <origin xyz="0 0 0.012" />
        <mass value="0.001" />
        <inertia ixx="0.00000001" ixy="0.0" ixz="0.0"
        iyy="0.00000001" iyz="0.0" izz="0.00000001" />
      </inertial>
    </link>
    <joint name="${prefix}${joint_prefix}J1" type="revolute">
      <parent link="${prefix}${link_prefix}middle" />
      <child link="${prefix}${link_prefix}_J1_dummy" />
      <origin xyz="0 0 0.02" rpy="0 0 0" />
      <axis xyz="1 0 0" />
      <limit lower="${20*M_PI/180}" upper="${20.1*M_PI/180}"
      effort="0.0" velocity="2.0" />
      <dynamics damping="0.5" />
    </joint>
    <gazebo reference="${prefix}${joint_prefix}J1">
      <provideFeedback>1</provideFeedback>
      <implicitSpringDamper>1</implicitSpringDamper>
    </gazebo>
    <xacro:middle_transmission muscletrans="${muscle}"
    prefix="${prefix}" joint_prefix="${joint_prefix}"
    link_prefix="${link_prefix}" />
    <link name="${prefix}${link_prefix}distal">
      <inertial>
        <origin xyz="0.0 -0.009 0.035" rpy="0 0 0" />
        <!-- approximated only FIXME -->
        <mass value="0.012" />
        <inertia ixx="0.00000094" ixy="0.0" ixz="0.0"
        iyy="0.0000011" iyz="0.0" izz="0.00000053" />
      </inertial>
      <visual>
        <origin xyz="0 0 0" rpy="0 0 0" />
        <geometry name="${prefix}${link_prefix}distal_visual">
          <!-- <mesh filename="package://sr_description/meshes/hand/biotacs/biotac.stl" scale="0.0254 0.0254 0.0254" /> -->
          <mesh filename="package://sr_description/meshes/hand/biotacs/biotac_decimated.dae"
          scale="0.0254 0.0254 0.0254" />
        </geometry>
      </visual>
      <collision>
        <geometry name="${prefix}${link_prefix}distal_collision_geom">

          <!-- <mesh filename="package://sr_description/meshes/hand/biotacs/biotac.stl" scale="0.0254 0.0254 0.0254" /> -->
          <mesh filename="package://sr_description/meshes/hand/biotacs/biotac_decimated.dae"
          scale="0.0254 0.0254 0.0254" />
        </geometry>
      </collision>
    </link>
    <gazebo reference="${prefix}${link_prefix}distal">
      <sensor type="contact"
      name="${prefix}${link_prefix}distal_contact">
        <always_on>1</always_on>
        <update_rate>1000.0</update_rate>
        <contact>
          <collision>
          ${prefix}${link_prefix}distal_collision</collision>
          <topic>${prefix}${link_prefix}distal_collision</topic>
        </contact>
        <plugin name="${prefix}${link_prefix}distal_gazebo_ros_bumper_controller"
        filename="libgazebo_ros_bumper.so">
          <updateRate>100.0</updateRate>
          <frameName>${prefix}${link_prefix}distal</frameName>
          <bumperTopicName>
          contacts/${prefix}${link_prefix}/distal</bumperTopicName>
        </plugin>
      </sensor>
      <selfCollide>true</selfCollide>
    </gazebo>
    <joint name="${prefix}${joint_prefix}_distal_joint"
    type="fixed">
      <parent link="${prefix}${link_prefix}middle" />
      <child link="${prefix}${link_prefix}distal" />
      <origin xyz="0 0.0 0.008" rpy="0 0 0" />
    </joint>
    <!-- extra link to imaginary sphere in fingertip for FK/IK calculations -->
    <!-- remove visual and collision once the correct position is found -->
    <link name="${prefix}${link_prefix}tip">
      <inertial>
        <mass value="0.001" />
        <origin xyz="0 0 0" rpy="0 0 0" />
        <inertia ixx="0.0" ixy="0.0" ixz="0.0" iyy="0.0" iyz="0.0"
        izz="0.0" />
      </inertial>
      <!--visual>
        <geometry>
          <sphere radius="0.002" />
        </geometry>
      </visual-->
    </link>
    <gazebo reference="${prefix}${joint_prefix}tip">
      <material name="Gazebo/RedGlow" />
    </gazebo>
    <joint name="${prefix}${joint_prefix}tip"
    type="fixed">
      <parent link="${prefix}${link_prefix}_J1_dummy" />
      <child link="${prefix}${link_prefix}tip" />
      <origin xyz="0.0 0.004 0.029" rpy="0 0 0" />
      <!-- approximated only FIXME -->
    </joint>
  </xacro:macro>
</robot>
