<?xml version="1.0" ?>
<!-- =================================================================================== -->
<!-- |    This document was autogenerated by xacro from yumi.urdf.xacro                | -->
<!-- |    EDITING THIS FILE BY HAND IS NOT RECOMMENDED                                 | -->
<!-- =================================================================================== -->
<robot name="yumi" xmlns:xacro="http://www.ros.org/wiki/xacro">
  <material name="Black">
    <color rgba="0.0 0.0 0.0 1.0"/>
  </material>
  <material name="Blue">
    <color rgba="0.0 0.0 0.8 1.0"/>
  </material>
  <material name="Green">
    <color rgba="0.0 0.8 0.0 1.0"/>
  </material>
  <material name="Grey">
    <color rgba="0.5 0.5 0.5 1.0"/>
  </material>
  <material name="Light_Grey">
    <color rgba="0.8 0.8 0.8 1.0"/>
  </material>
  <material name="Ivory">
    <color rgba="1.0 1.0 0.94 1.0"/>
  </material>
  <material name="Orange">
    <color rgba="1.0 0.423529411765 0.0392156862745 1.0"/>
  </material>
  <material name="Brown">
    <color rgba="0.870588235294 0.811764705882 0.764705882353 1.0"/>
  </material>
  <material name="Red">
    <color rgba="0.8 0.0 0.0 1.0"/>
  </material>
  <material name="White">
    <color rgba="1.0 1.0 1.0 1.0"/>
  </material>
  <gazebo>
    <plugin filename="libgazebo_ros_control.so" name="gazebo_ros_controller">
      <robotNamespace>/yumi</robotNamespace>
    </plugin>
  </gazebo>
  <link name="yumi_base_link"/>
  <joint name="yumi_base_link_to_body" type="fixed">
    <parent link="yumi_base_link"/>
    <child link="yumi_body"/>
    <origin rpy="0 0 0" xyz="0 0 0"/>
  </joint>
  <link name="yumi_body">
    <inertial>
      <origin rpy="0 0 0" xyz="0 0 0"/>
      <mass value="15"/>
      <inertia ixx="0.5" ixy="0" ixz="0" iyy="0.6" iyz="0" izz="0.3"/>
    </inertial>
    <visual>
      <origin rpy="0 0 0" xyz="0 0 0"/>
      <geometry>
        <mesh filename="package://yumi_description/meshes/body.stl"/>
      </geometry>
      <material name="Light_Grey"/>
    </visual>
    <collision>
      <origin rpy="0 0 0" xyz="0 0 0"/>
      <geometry>
        <mesh filename="package://yumi_description/meshes/coarse/body.stl"/>
      </geometry>
      <material name="Light_Grey"/>
    </collision>
  </link>
  <!--///////////////////////////////////// RIGHT ARM ////////////////////////////////  -->
  <!-- joint between body and link_1_r -->
  <joint name="yumi_joint_1_r" type="revolute">
    <parent link="yumi_body"/>
    <child link="yumi_link_1_r"/>
    <origin rpy="-0.9795   -0.5682   -2.3155" xyz="0.05355 -0.0725 0.41492"/>
    <axis xyz="0 0 1"/>
    <limit effort="300" lower="-2.94087978961" upper="2.94087978961" velocity="3.14159265359"/>
    <dynamics damping="0.5"/>
  </joint>
  <link name="yumi_link_1_r">
    <inertial>
      <origin rpy="0 0 0" xyz="0 -0.03 0.12"/>
      <mass value="2"/>
      <inertia ixx="0.1" ixy="0" ixz="0" iyy="0.1" iyz="0" izz="0.1"/>
    </inertial>
    <visual>
      <origin rpy="0 0 0" xyz="0 0 0"/>
      <geometry>
        <mesh filename="package://yumi_description/meshes/link_1.stl"/>
      </geometry>
      <material name="Grey"/>
    </visual>
    <collision>
      <origin rpy="0 0 0" xyz="0 0 0"/>
      <geometry>
        <mesh filename="package://yumi_description/meshes/coarse/link_1.stl"/>
      </geometry>
      <material name="Grey"/>
    </collision>
  </link>
  <!-- joint between link_1_r and link_2_r -->
  <joint name="yumi_joint_2_r" type="revolute">
    <parent link="yumi_link_1_r"/>
    <child link="yumi_link_2_r"/>
    <origin rpy="1.57079632679 0.0 0.0" xyz="0.03 0.0 0.1"/>
    <axis xyz="0 0 1"/>
    <limit effort="300" lower="-2.50454747661" upper="0.759218224618" velocity="3.14159265359"/>
    <dynamics damping="0.5"/>
  </joint>
  <link name="yumi_link_2_r">
    <inertial>
      <origin rpy="0 0 0" xyz="0 0 0"/>
      <mass value="2"/>
      <inertia ixx="0.1" ixy="0" ixz="0" iyy="0.1" iyz="0" izz="0.1"/>
    </inertial>
    <visual>
      <origin rpy="0 0 0" xyz="0 0 0"/>
      <geometry>
        <mesh filename="package://yumi_description/meshes/link_2.stl"/>
      </geometry>
      <material name="Grey"/>
    </visual>
    <collision>
      <origin rpy="0 0 0" xyz="0 0 0"/>
      <geometry>
        <mesh filename="package://yumi_description/meshes/coarse/link_2.stl"/>
      </geometry>
      <material name="Grey"/>
    </collision>
  </link>
  <!-- joint between link_2_r and link_3_r -->
  <joint name="yumi_joint_7_r" type="revolute">
    <parent link="yumi_link_2_r"/>
    <child link="yumi_link_3_r"/>
    <origin rpy="-1.57079632679 0.0 0.0" xyz="-0.03 0.17283 0.0"/>
    <axis xyz="0 0 1"/>
    <limit effort="300" lower="-2.94087978961" upper="2.94087978961" velocity="3.14159265359"/>
    <dynamics damping="0.5"/>
  </joint>
  <link name="yumi_link_3_r">
    <inertial>
      <origin rpy="0 0 0" xyz="0 0 0"/>
      <mass value="2"/>
      <inertia ixx="0.1" ixy="0" ixz="0" iyy="0.1" iyz="0" izz="0.1"/>
    </inertial>
    <visual>
      <origin rpy="0 0 0" xyz="0 0 0"/>
      <geometry>
        <mesh filename="package://yumi_description/meshes/link_3.stl"/>
      </geometry>
      <material name="Grey"/>
    </visual>
    <collision>
      <origin rpy="0 0 0" xyz="0 0 0"/>
      <geometry>
        <mesh filename="package://yumi_description/meshes/coarse/link_3.stl"/>
      </geometry>
      <material name="Grey"/>
    </collision>
  </link>
  <!-- joint between link_3_r and link_4_r -->
  <joint name="yumi_joint_3_r" type="revolute">
    <parent link="yumi_link_3_r"/>
    <child link="yumi_link_4_r"/>
    <origin rpy="1.57079632679 -1.57079632679 0.0" xyz="-0.04188 0.0 0.07873"/>
    <axis xyz="0 0 1"/>
    <limit effort="300" lower="-2.15548162621" upper="1.3962634016" velocity="3.14159265359"/>
    <dynamics damping="0.5"/>
  </joint>
  <link name="yumi_link_4_r">
    <inertial>
      <origin rpy="0 0 0" xyz="0 0 0"/>
      <mass value="2"/>
      <inertia ixx="0.1" ixy="0" ixz="0" iyy="0.1" iyz="0" izz="0.1"/>
    </inertial>
    <visual>
      <origin rpy="0 0 0" xyz="0 0 0"/>
      <geometry>
        <mesh filename="package://yumi_description/meshes/link_4.stl"/>
      </geometry>
      <material name="Grey"/>
    </visual>
    <collision>
      <origin rpy="0 0 0" xyz="0 0 0"/>
      <geometry>
        <mesh filename="package://yumi_description/meshes/coarse/link_4.stl"/>
      </geometry>
      <material name="Grey"/>
    </collision>
  </link>
  <!-- joint between link_4_r and link_5_r -->
  <joint name="yumi_joint_4_r" type="revolute">
    <parent link="yumi_link_4_r"/>
    <child link="yumi_link_5_r"/>
    <origin rpy="-1.57079632679 0.0 0.0" xyz="0.0405 0.16461 0.0"/>
    <axis xyz="0 0 1"/>
    <limit effort="300" lower="-5.06145483078" upper="5.06145483078" velocity="6.98131700798"/>
    <dynamics damping="0.5"/>
  </joint>
  <link name="yumi_link_5_r">
    <inertial>
      <origin rpy="0 0 0" xyz="0 0 0"/>
      <mass value="2"/>
      <inertia ixx="0.1" ixy="0" ixz="0" iyy="0.1" iyz="0" izz="0.1"/>
    </inertial>
    <visual>
      <origin rpy="0 0 0" xyz="0 0 0"/>
      <geometry>
        <mesh filename="package://yumi_description/meshes/link_5.stl"/>
      </geometry>
      <material name="Grey"/>
    </visual>
    <collision>
      <origin rpy="0 0 0" xyz="0 0 0"/>
      <geometry>
        <mesh filename="package://yumi_description/meshes/coarse/link_5.stl"/>
      </geometry>
      <material name="Grey"/>
    </collision>
  </link>
  <!-- joint between link_5_r and link_6_r -->
  <joint name="yumi_joint_5_r" type="revolute">
    <parent link="yumi_link_5_r"/>
    <child link="yumi_link_6_r"/>
    <origin rpy="1.57079632679 0.0 0.0" xyz="-0.027 0 0.10039"/>
    <axis xyz="0 0 1"/>
    <limit effort="300" lower="-1.53588974176" upper="2.40855436775" velocity="6.98131700798"/>
    <dynamics damping="0.5"/>
  </joint>
  <link name="yumi_link_6_r">
    <inertial>
      <origin rpy="0 0 0" xyz="0 0 0"/>
      <mass value="2"/>
      <inertia ixx="0.1" ixy="0" ixz="0" iyy="0.1" iyz="0" izz="0.1"/>
    </inertial>
    <visual>
      <origin rpy="0 0 0" xyz="0 0 0"/>
      <geometry>
        <mesh filename="package://yumi_description/meshes/link_6.stl"/>
      </geometry>
      <material name="Grey"/>
    </visual>
    <collision>
      <origin rpy="0 0 0" xyz="0 0 0"/>
      <geometry>
        <mesh filename="package://yumi_description/meshes/coarse/link_6.stl"/>
      </geometry>
      <material name="Grey"/>
    </collision>
  </link>
  <!-- joint between link_6_r and link_7_r -->
  <joint name="yumi_joint_6_r" type="revolute">
    <parent link="yumi_link_6_r"/>
    <child link="yumi_link_7_r"/>
    <origin rpy="-1.57079632679 0.0 0.0" xyz="0.027 0.029 0.0"/>
    <axis xyz="0 0 1"/>
    <limit effort="300" lower="-3.99680398707" upper="3.99680398707" velocity="6.98131700798"/>
    <dynamics damping="0.5"/>
  </joint>
  <link name="yumi_link_7_r">
    <inertial>
      <origin rpy="0 0 0" xyz="0 0 0"/>
      <mass value="2"/>
      <inertia ixx="0.1" ixy="0" ixz="0" iyy="0.1" iyz="0" izz="0.1"/>
    </inertial>
    <visual>
      <origin rpy="0 0 0" xyz="0 0 0"/>
      <geometry>
        <mesh filename="package://yumi_description/meshes/link_7.stl"/>
      </geometry>
      <material name="Grey"/>
    </visual>
    <collision>
      <origin rpy="0 0 0" xyz="0 0 0"/>
      <geometry>
        <mesh filename="package://yumi_description/meshes/coarse/link_7.stl"/>
      </geometry>
      <material name="Grey"/>
    </collision>
  </link>
  <!--///////////////////////////////////// LEFT ARM ////////////////////////////////  -->
  <!-- joint between body and link_1_l -->
  <joint name="yumi_joint_1_l" type="revolute">
    <parent link="yumi_body"/>
    <child link="yumi_link_1_l"/>
    <origin rpy="0.9781 -0.5716 2.3180" xyz="0.05355 0.07250 0.41492"/>
    <axis xyz="0 0 1"/>
    <limit effort="300" lower="-2.94087978961" upper="2.94087978961" velocity="3.14159265359"/>
    <dynamics damping="0.5"/>
  </joint>
  <link name="yumi_link_1_l">
    <inertial>
      <origin rpy="0 0 0" xyz="0 -0.03 0.12"/>
      <mass value="2"/>
      <inertia ixx="0.1" ixy="0" ixz="0" iyy="0.1" iyz="0" izz="0.1"/>
    </inertial>
    <visual>
      <origin rpy="0 0 0" xyz="0 0 0"/>
      <geometry>
        <mesh filename="package://yumi_description/meshes/link_1.stl"/>
      </geometry>
      <material name="Grey"/>
    </visual>
    <collision>
      <origin rpy="0 0 0" xyz="0 0 0"/>
      <geometry>
        <mesh filename="package://yumi_description/meshes/coarse/link_1.stl"/>
      </geometry>
      <material name="Grey"/>
    </collision>
  </link>
  <!-- joint between link_1_l and link_2_l -->
  <joint name="yumi_joint_2_l" type="revolute">
    <parent link="yumi_link_1_l"/>
    <child link="yumi_link_2_l"/>
    <origin rpy="1.57079632679 0.0 0.0" xyz="0.03 0.0 0.1"/>
    <axis xyz="0 0 1"/>
    <limit effort="300" lower="-2.50454747661" upper="0.759218224618" velocity="3.14159265359"/>
    <dynamics damping="0.5"/>
  </joint>
  <link name="yumi_link_2_l">
    <inertial>
      <origin rpy="0 0 0" xyz="0 0 0"/>
      <mass value="2"/>
      <inertia ixx="0.1" ixy="0" ixz="0" iyy="0.1" iyz="0" izz="0.1"/>
    </inertial>
    <visual>
      <origin rpy="0 0 0" xyz="0 0 0"/>
      <geometry>
        <mesh filename="package://yumi_description/meshes/link_2.stl"/>
      </geometry>
      <material name="Grey"/>
    </visual>
    <collision>
      <origin rpy="0 0 0" xyz="0 0 0"/>
      <geometry>
        <mesh filename="package://yumi_description/meshes/coarse/link_2.stl"/>
      </geometry>
      <material name="Grey"/>
    </collision>
  </link>
  <!-- joint between link_2_l and link_3_l -->
  <joint name="yumi_joint_7_l" type="revolute">
    <parent link="yumi_link_2_l"/>
    <child link="yumi_link_3_l"/>
    <origin rpy="-1.57079632679 0.0 0.0" xyz="-0.03 0.17283 0.0"/>
    <axis xyz="0 0 1"/>
    <limit effort="300" lower="-2.94087978961" upper="2.94087978961" velocity="3.14159265359"/>
    <dynamics damping="0.5"/>
  </joint>
  <link name="yumi_link_3_l">
    <inertial>
      <origin rpy="0 0 0" xyz="0 0 0"/>
      <mass value="2"/>
      <inertia ixx="0.1" ixy="0" ixz="0" iyy="0.1" iyz="0" izz="0.1"/>
    </inertial>
    <visual>
      <origin rpy="0 0 0" xyz="0 0 0"/>
      <geometry>
        <mesh filename="package://yumi_description/meshes/link_3.stl"/>
      </geometry>
      <material name="Grey"/>
    </visual>
    <collision>
      <origin rpy="0 0 0" xyz="0 0 0"/>
      <geometry>
        <mesh filename="package://yumi_description/meshes/coarse/link_3.stl"/>
      </geometry>
      <material name="Grey"/>
    </collision>
  </link>
  <!-- joint between link_3_l and link_4_l -->
  <joint name="yumi_joint_3_l" type="revolute">
    <parent link="yumi_link_3_l"/>
    <child link="yumi_link_4_l"/>
    <origin rpy="1.57079632679 -1.57079632679 0.0" xyz="-0.04188 0.0 0.07873"/>
    <axis xyz="0 0 1"/>
    <limit effort="300" lower="-2.15548162621" upper="1.3962634016" velocity="3.14159265359"/>
    <dynamics damping="0.5"/>
  </joint>
  <link name="yumi_link_4_l">
    <inertial>
      <origin rpy="0 0 0" xyz="0 0 0"/>
      <mass value="2"/>
      <inertia ixx="0.1" ixy="0" ixz="0" iyy="0.1" iyz="0" izz="0.1"/>
    </inertial>
    <visual>
      <origin rpy="0 0 0" xyz="0 0 0"/>
      <geometry>
        <mesh filename="package://yumi_description/meshes/link_4.stl"/>
      </geometry>
      <material name="Grey"/>
    </visual>
    <collision>
      <origin rpy="0 0 0" xyz="0 0 0"/>
      <geometry>
        <mesh filename="package://yumi_description/meshes/coarse/link_4.stl"/>
      </geometry>
      <material name="Grey"/>
    </collision>
  </link>
  <!-- joint between link_4_l and link_5_l -->
  <joint name="yumi_joint_4_l" type="revolute">
    <parent link="yumi_link_4_l"/>
    <child link="yumi_link_5_l"/>
    <origin rpy="-1.57079632679 0.0 0.0" xyz="0.0405 0.16461 0.0"/>
    <axis xyz="0 0 1"/>
    <limit effort="300" lower="-5.06145483078" upper="5.06145483078" velocity="6.98131700798"/>
    <dynamics damping="0.5"/>
  </joint>
  <link name="yumi_link_5_l">
    <inertial>
      <origin rpy="0 0 0" xyz="0 0 0"/>
      <mass value="2"/>
      <inertia ixx="0.1" ixy="0" ixz="0" iyy="0.1" iyz="0" izz="0.1"/>
    </inertial>
    <visual>
      <origin rpy="0 0 0" xyz="0 0 0"/>
      <geometry>
        <mesh filename="package://yumi_description/meshes/link_5.stl"/>
      </geometry>
      <material name="Grey"/>
    </visual>
    <collision>
      <origin rpy="0 0 0" xyz="0 0 0"/>
      <geometry>
        <mesh filename="package://yumi_description/meshes/coarse/link_5.stl"/>
      </geometry>
      <material name="Grey"/>
    </collision>
  </link>
  <!-- joint between link_5_l and link_6_l -->
  <joint name="yumi_joint_5_l" type="revolute">
    <parent link="yumi_link_5_l"/>
    <child link="yumi_link_6_l"/>
    <origin rpy="1.57079632679 0.0 0.0" xyz="-0.027 0 0.10039"/>
    <axis xyz="0 0 1"/>
    <limit effort="300" lower="-1.53588974176" upper="2.40855436775" velocity="6.98131700798"/>
    <dynamics damping="0.5"/>
  </joint>
  <link name="yumi_link_6_l">
    <inertial>
      <origin rpy="0 0 0" xyz="0 0 0"/>
      <mass value="2"/>
      <inertia ixx="0.1" ixy="0" ixz="0" iyy="0.1" iyz="0" izz="0.1"/>
    </inertial>
    <visual>
      <origin rpy="0 0 0" xyz="0 0 0"/>
      <geometry>
        <mesh filename="package://yumi_description/meshes/link_6.stl"/>
      </geometry>
      <material name="Grey"/>
    </visual>
    <collision>
      <origin rpy="0 0 0" xyz="0 0 0"/>
      <geometry>
        <mesh filename="package://yumi_description/meshes/coarse/link_6.stl"/>
      </geometry>
      <material name="Grey"/>
    </collision>
  </link>
  <!-- joint between link_6_l and link_7_l -->
  <joint name="yumi_joint_6_l" type="revolute">
    <parent link="yumi_link_6_l"/>
    <child link="yumi_link_7_l"/>
    <origin rpy="-1.57079632679 0.0 0.0" xyz="0.027 0.029 0.0"/>
    <axis xyz="0 0 1"/>
    <limit effort="300" lower="-3.99680398707" upper="3.99680398707" velocity="6.98131700798"/>
    <dynamics damping="0.5"/>
  </joint>
  <link name="yumi_link_7_l">
    <inertial>
      <origin rpy="0 0 0" xyz="0 0 0"/>
      <mass value="2"/>
      <inertia ixx="0.1" ixy="0" ixz="0" iyy="0.1" iyz="0" izz="0.1"/>
    </inertial>
    <visual>
      <origin rpy="0 0 0" xyz="0 0 0"/>
      <geometry>
        <mesh filename="package://yumi_description/meshes/link_7.stl"/>
      </geometry>
      <material name="Grey"/>
    </visual>
    <collision>
      <origin rpy="0 0 0" xyz="0 0 0"/>
      <geometry>
        <mesh filename="package://yumi_description/meshes/coarse/link_7.stl"/>
      </geometry>
      <material name="Grey"/>
    </collision>
  </link>
  <!-- Gazebo reference frame -->
  <gazebo reference="yumi_body">
    <material>Gazebo/Ivory</material>
    <mu1>0.2</mu1>
    <mu2>0.2</mu2>
  </gazebo>
  <transmission name="yumi_tran_1_r">
    <type>transmission_interface/SimpleTransmission</type>
    <joint name="yumi_joint_1_r">
      <hardwareInterface>hardware_interface/VelocityJointInterface</hardwareInterface>
    </joint>
    <actuator name="yumi_motor_1_r">
      <hardwareInterface>hardware_interface/VelocityJointInterface</hardwareInterface>
      <mechanicalReduction>1</mechanicalReduction>
    </actuator>
  </transmission>
  <transmission name="yumi_tran_2_r">
    <type>transmission_interface/SimpleTransmission</type>
    <joint name="yumi_joint_2_r">
      <hardwareInterface>hardware_interface/VelocityJointInterface</hardwareInterface>
    </joint>
    <actuator name="yumi_motor_2_r">
      <hardwareInterface>hardware_interface/VelocityJointInterface</hardwareInterface>
      <mechanicalReduction>1</mechanicalReduction>
    </actuator>
  </transmission>
  <transmission name="yumi_tran_3_r">
    <type>transmission_interface/SimpleTransmission</type>
    <joint name="yumi_joint_3_r">
      <hardwareInterface>hardware_interface/VelocityJointInterface</hardwareInterface>
    </joint>
    <actuator name="yumi_motor_3_r">
      <hardwareInterface>hardware_interface/VelocityJointInterface</hardwareInterface>
      <mechanicalReduction>1</mechanicalReduction>
    </actuator>
  </transmission>
  <transmission name="yumi_tran_4_r">
    <type>transmission_interface/SimpleTransmission</type>
    <joint name="yumi_joint_4_r">
      <hardwareInterface>hardware_interface/VelocityJointInterface</hardwareInterface>
    </joint>
    <actuator name="yumi_motor_4_r">
      <hardwareInterface>hardware_interface/VelocityJointInterface</hardwareInterface>
      <mechanicalReduction>1</mechanicalReduction>
    </actuator>
  </transmission>
  <transmission name="yumi_tran_5_r">
    <type>transmission_interface/SimpleTransmission</type>
    <joint name="yumi_joint_5_r">
      <hardwareInterface>hardware_interface/VelocityJointInterface</hardwareInterface>
    </joint>
    <actuator name="yumi_motor_5_r">
      <hardwareInterface>hardware_interface/VelocityJointInterface</hardwareInterface>
      <mechanicalReduction>1</mechanicalReduction>
    </actuator>
  </transmission>
  <transmission name="yumi_tran_6_r">
    <type>transmission_interface/SimpleTransmission</type>
    <joint name="yumi_joint_6_r">
      <hardwareInterface>hardware_interface/VelocityJointInterface</hardwareInterface>
    </joint>
    <actuator name="yumi_motor_6_r">
      <hardwareInterface>hardware_interface/VelocityJointInterface</hardwareInterface>
      <mechanicalReduction>1</mechanicalReduction>
    </actuator>
  </transmission>
  <transmission name="yumi_tran_7_r">
    <type>transmission_interface/SimpleTransmission</type>
    <joint name="yumi_joint_7_r">
      <hardwareInterface>hardware_interface/VelocityJointInterface</hardwareInterface>
    </joint>
    <actuator name="yumi_motor_7_r">
      <hardwareInterface>hardware_interface/VelocityJointInterface</hardwareInterface>
      <mechanicalReduction>1</mechanicalReduction>
    </actuator>
  </transmission>
  <transmission name="yumi_tran_1_l">
    <type>transmission_interface/SimpleTransmission</type>
    <joint name="yumi_joint_1_l">
      <hardwareInterface>hardware_interface/VelocityJointInterface</hardwareInterface>
    </joint>
    <actuator name="yumi_motor_1_l">
      <hardwareInterface>hardware_interface/VelocityJointInterface</hardwareInterface>
      <mechanicalReduction>1</mechanicalReduction>
    </actuator>
  </transmission>
  <transmission name="yumi_tran_2_l">
    <type>transmission_interface/SimpleTransmission</type>
    <joint name="yumi_joint_2_l">
      <hardwareInterface>hardware_interface/VelocityJointInterface</hardwareInterface>
    </joint>
    <actuator name="yumi_motor_2_l">
      <hardwareInterface>hardware_interface/VelocityJointInterface</hardwareInterface>
      <mechanicalReduction>1</mechanicalReduction>
    </actuator>
  </transmission>
  <transmission name="yumi_tran_3_l">
    <type>transmission_interface/SimpleTransmission</type>
    <joint name="yumi_joint_3_l">
      <hardwareInterface>hardware_interface/VelocityJointInterface</hardwareInterface>
    </joint>
    <actuator name="yumi_motor_3_l">
      <hardwareInterface>hardware_interface/VelocityJointInterface</hardwareInterface>
      <mechanicalReduction>1</mechanicalReduction>
    </actuator>
  </transmission>
  <transmission name="yumi_tran_4_l">
    <type>transmission_interface/SimpleTransmission</type>
    <joint name="yumi_joint_4_l">
      <hardwareInterface>hardware_interface/VelocityJointInterface</hardwareInterface>
    </joint>
    <actuator name="yumi_motor_4_l">
      <hardwareInterface>hardware_interface/VelocityJointInterface</hardwareInterface>
      <mechanicalReduction>1</mechanicalReduction>
    </actuator>
  </transmission>
  <transmission name="yumi_tran_5_l">
    <type>transmission_interface/SimpleTransmission</type>
    <joint name="yumi_joint_5_l">
      <hardwareInterface>hardware_interface/VelocityJointInterface</hardwareInterface>
    </joint>
    <actuator name="yumi_motor_5_l">
      <hardwareInterface>hardware_interface/VelocityJointInterface</hardwareInterface>
      <mechanicalReduction>1</mechanicalReduction>
    </actuator>
  </transmission>
  <transmission name="yumi_tran_6_l">
    <type>transmission_interface/SimpleTransmission</type>
    <joint name="yumi_joint_6_l">
      <hardwareInterface>hardware_interface/VelocityJointInterface</hardwareInterface>
    </joint>
    <actuator name="yumi_motor_6_l">
      <hardwareInterface>hardware_interface/VelocityJointInterface</hardwareInterface>
      <mechanicalReduction>1</mechanicalReduction>
    </actuator>
  </transmission>
  <transmission name="yumi_tran_7_l">
    <type>transmission_interface/SimpleTransmission</type>
    <joint name="yumi_joint_7_l">
      <hardwareInterface>hardware_interface/VelocityJointInterface</hardwareInterface>
    </joint>
    <actuator name="yumi_motor_7_l">
      <hardwareInterface>hardware_interface/VelocityJointInterface</hardwareInterface>
      <mechanicalReduction>1</mechanicalReduction>
    </actuator>
  </transmission>


  <link name="world"/>
  <joint name="world_joint" type="fixed">
    <parent link="world"/>
    <child link="yumi_base_link"/>
    <origin rpy="0 0 0" xyz="0 0 0.1"/>
  </joint>



  <!-- GRIPPER PARTS BELOW -->
 
<!-- LEFT HAND part-->
<joint name="yumi_link_7_l_joint" type="fixed">
  <parent link="yumi_link_7_l" />
  <child link="left_hand_base" />
  <origin rpy="0 0 3.1415" xyz="0 0 0"/>
</joint>

  <!-- Create a new base frame for convenience, by LYW, 2019/11/22 -->
  <link name="left_hand_base">
    <!-- Add visual tag for calibration -->
    <!--visual>
      <origin xyz="0 0 -0.025" rpy="0 0 0" />
      <geometry>
        <cylinder radius="0.0279" length="0.05" /> <!- - diameter is 55.8 mm according to the technical specifics- ->
      </geometry>
    </visual-->
  </link>

  <!-- Fix frame of reference through solidworks measurement and manual calibration, by LYW, 2019/11/22 -->
  <joint name="link111_shift" type="fixed">
    <origin xyz="-0.00850 -0.0190 0.0404" rpy="3.1415 0 -1.5707" /> <!--0.00985 0.02039 0.0404-->
    <parent link="left_hand_base" />
    <child link="link111" />
  </joint>


  <link
    name="link111">
    <inertial>
      <origin
        xyz="-0.0211971496867713 -0.00980607468332059 -0.0291539210995797"
        rpy="0 0 0" />
      <mass
        value="0.226288892912552" />
      <inertia
        ixx="0.00025807950453196"
        ixy="-4.83159310640912E-06"
        ixz="7.9714751769554E-07"
        iyy="0.000358691949590454"
        iyz="3.73467589382574E-06"
        izz="0.000161017137787831" />
    </inertial>
    <visual>
      <origin
        xyz="0 0 0"
        rpy="0 0 0" />
      <geometry>
        <mesh
          filename="package://inspire_hand_description/meshes/left/link111.STL" />
      </geometry>
      <material
        name="">
        <color
          rgba="0.827450980392157 0.83921568627451 0.827450980392157 1" />
      </material>
    </visual>
    <collision>
      <origin
        xyz="0 0 0"
        rpy="0 0 0" />
      <geometry>
        <mesh
          filename="package://inspire_hand_description/meshes/left/link111.STL" />
      </geometry>
    </collision>
  </link>
  <link
    name="link1">
    <inertial>
      <origin
        xyz="0.0107728972114067 0.00213787716764519 -1.04416311069722E-07"
        rpy="0 0 0" />
      <mass
        value="0.00330630285835291" />
      <inertia
        ixx="1.55839473420917E-07"
        ixy="-3.78961194376192E-08"
        ixz="-3.77173039190185E-12"
        iyy="5.30393024372046E-07"
        iyz="-7.4062368302925E-13"
        izz="5.55170037339627E-07" />
    </inertial>
    <visual>
      <origin
        xyz="0 0 0"
        rpy="0 0 0" />
      <geometry>
        <mesh
          filename="package://inspire_hand_description/meshes/left/link1.STL" />
      </geometry>
      <material
        name="">
        <color
          rgba="0.792156862745098 0.819607843137255 0.933333333333333 1" />
      </material>
    </visual>
    <collision>
      <origin
        xyz="0 0 0"
        rpy="0 0 0" />
      <geometry>
        <mesh
          filename="package://inspire_hand_description/meshes/left/link1.STL" />
      </geometry>
    </collision>
  </link>
  <joint
    name="link1"
    type="revolute">
    <origin
      xyz="0.0068852 -0.0077547 -0.08206"
      rpy="-1.4604 1.2485 -1.466" />
    <parent
      link="link111" />
    <child
      link="link1" />
    <axis
      xyz="0 0 1" />
    <limit
      lower="-1.6"
      upper="0"
      effort="1"
      velocity="1" />
  </joint>
  <link
    name="link11">
    <inertial>
      <origin
        xyz="0.0190179143887291 0.00563447080965412 1.42999243835096E-08"
        rpy="0 0 0" />
      <mass
        value="0.00453366979354947" />
      <inertia
        ixx="8.56969401817861E-08"
        ixy="-3.6550236316683E-08"
        ixz="1.43626963228685E-12"
        iyy="7.5823333421962E-07"
        iyz="7.37235171817566E-13"
        izz="7.68832168975162E-07" />
    </inertial>
    <visual>
      <origin
        xyz="0 0 0"
        rpy="0 0 0" />
      <geometry>
        <mesh
          filename="package://inspire_hand_description/meshes/left/link11.STL" />
      </geometry>
      <material
        name="">
        <color
          rgba="1 1 1 1" />
      </material>
    </visual>
    <collision>
      <origin
        xyz="0 0 0"
        rpy="0 0 0" />
      <geometry>
        <mesh
          filename="package://inspire_hand_description/meshes/left/link11.STL" />
      </geometry>
    </collision>
  </link>
  <joint
    name="link11"
    type="revolute">
    <origin
      xyz="0.032132 0 0"
      rpy="-5.2101E-10 -2.8366E-11 -0.05439" />
    <parent
      link="link1" />
    <child
      link="link11" />
    <axis
      xyz="0 0 1" />
    <limit
      lower="-1.7"
      upper="0"
      effort="1"
      velocity="1" />
  </joint>
  <link
    name="link2">
    <inertial>
      <origin
        xyz="0.0107729848426235 0.00213783905889497 -1.15186638033338E-07"
        rpy="0 0 0" />
      <mass
        value="0.00330621735666597" />
      <inertia
        ixx="1.55837836898236E-07"
        ixy="-3.78957279466946E-08"
        ixz="-4.46779108562076E-12"
        iyy="5.30385092299547E-07"
        iyz="-1.06162548544094E-12"
        izz="5.5516472017082E-07" />
    </inertial>
    <visual>
      <origin
        xyz="0 0 0"
        rpy="0 0 0" />
      <geometry>
        <mesh
          filename="package://inspire_hand_description/meshes/left/link2.STL" />
      </geometry>
      <material
        name="">
        <color
          rgba="0.792156862745098 0.819607843137255 0.933333333333333 1" />
      </material>
    </visual>
    <collision>
      <origin
        xyz="0 0 0"
        rpy="0 0 0" />
      <geometry>
        <mesh
          filename="package://inspire_hand_description/meshes/left/link2.STL" />
      </geometry>
    </collision>
  </link>
  <joint
    name="link2"
    type="revolute">
    <origin
      xyz="-0.012436 -0.0077547 -0.082423"
      rpy="-1.5708 1.4093 -1.5708" />
    <parent
      link="link111" />
    <child
      link="link2" />
    <axis
      xyz="0 0 1" />
    <limit
      lower="-1.6"
      upper="0"
      effort="1"
      velocity="1" />
  </joint>
  <link
    name="link22">
    <inertial>
      <origin
        xyz="0.0190179449257988 0.00563447974623821 1.95695375043714E-08"
        rpy="0 0 0" />
      <mass
        value="0.00453367027223764" />
      <inertia
        ixx="8.56969657851684E-08"
        ixy="-3.655092334419E-08"
        ixz="1.59947670219807E-12"
        iyy="7.58233058731142E-07"
        iyz="6.82745605693632E-13"
        izz="7.68832058388577E-07" />
    </inertial>
    <visual>
      <origin
        xyz="0 0 0"
        rpy="0 0 0" />
      <geometry>
        <mesh
          filename="package://inspire_hand_description/meshes/left/link22.STL" />
      </geometry>
      <material
        name="">
        <color
          rgba="1 1 1 1" />
      </material>
    </visual>
    <collision>
      <origin
        xyz="0 0 0"
        rpy="0 0 0" />
      <geometry>
        <mesh
          filename="package://inspire_hand_description/meshes/left/link22.STL" />
      </geometry>
    </collision>
  </link>
  <joint
    name="link22"
    type="revolute">
    <origin
      xyz="0.032132 0 0"
      rpy="-5.0853E-10 -1.1686E-10 -0.22588" />
    <parent
      link="link2" />
    <child
      link="link22" />
    <axis
      xyz="0 0 1" />
    <limit
      lower="-1.7"
      upper="0"
      effort="1"
      velocity="1" />
  </joint>
  <link
    name="link3">
    <inertial>
      <origin
        xyz="0.0107730870011274 0.00213783984115729 -1.4434440405442E-07"
        rpy="0 0 0" />
      <mass
        value="0.00330616517571661" />
      <inertia
        ixx="1.55836709865158E-07"
        ixy="-3.78959914486162E-08"
        ixz="-4.87563626733582E-12"
        iyy="5.30380857158255E-07"
        iyz="-1.32040927550488E-12"
        izz="5.55162479884557E-07" />
    </inertial>
    <visual>
      <origin
        xyz="0 0 0"
        rpy="0 0 0" />
      <geometry>
        <mesh
          filename="package://inspire_hand_description/meshes/left/link3.STL" />
      </geometry>
      <material
        name="">
        <color
          rgba="0.792156862745098 0.819607843137255 0.933333333333333 1" />
      </material>
    </visual>
    <collision>
      <origin
        xyz="0 0 0"
        rpy="0 0 0" />
      <geometry>
        <mesh
          filename="package://inspire_hand_description/meshes/left/link3.STL" />
      </geometry>
    </collision>
  </link>
  <joint
    name="link3"
    type="revolute">
    <origin
      xyz="-0.031665 -0.0077547 -0.08192"
      rpy="-1.9857 1.4406 -1.9826" />
    <parent
      link="link111" />
    <child
      link="link3" />
    <axis
      xyz="0 0 1" />
    <limit
      lower="-1.6"
      upper="0"
      effort="1"
      velocity="1" />
  </joint>
  <link
    name="link33">
    <inertial>
      <origin
        xyz="0.0190179173374263 0.00563447812355383 2.17778843153438E-08"
        rpy="0 0 0" />
      <mass
        value="0.00453366946672897" />
      <inertia
        ixx="8.56969954123567E-08"
        ixy="-3.65502686172672E-08"
        ixz="1.914131820864E-12"
        iyy="7.58232390943582E-07"
        iyz="6.102905747127E-13"
        izz="7.68831206632801E-07" />
    </inertial>
    <visual>
      <origin
        xyz="0 0 0"
        rpy="0 0 0" />
      <geometry>
        <mesh
          filename="package://inspire_hand_description/meshes/left/link33.STL" />
      </geometry>
      <material
        name="">
        <color
          rgba="1 1 1 1" />
      </material>
    </visual>
    <collision>
      <origin
        xyz="0 0 0"
        rpy="0 0 0" />
      <geometry>
        <mesh
          filename="package://inspire_hand_description/meshes/left/link33.STL" />
      </geometry>
    </collision>
  </link>
  <joint
    name="link33"
    type="revolute">
    <origin
      xyz="0.032132 0 0"
      rpy="-5.0314E-10 -1.3824E-10 -0.26815" />
    <parent
      link="link3" />
    <child
      link="link33" />
    <axis
      xyz="0 0 1" />
    <limit
      lower="-1.7"
      upper="0"
      effort="1"
      velocity="1" />
  </joint>
  <link
    name="link4">
    <inertial>
      <origin
        xyz="0.0107728838996999 0.00213787812202321 -1.47685512180695E-07"
        rpy="0 0 0" />
      <mass
        value="0.00330630460851054" />
      <inertia
        ixx="1.55839834881808E-07"
        ixy="-3.78966413485388E-08"
        ixz="-5.46215465743034E-12"
        iyy="5.3039377562325E-07"
        iyz="-1.57695349654339E-12"
        izz="5.55171477054147E-07" />
    </inertial>
    <visual>
      <origin
        xyz="0 0 0"
        rpy="0 0 0" />
      <geometry>
        <mesh
          filename="package://inspire_hand_description/meshes/left/link4.STL" />
      </geometry>
      <material
        name="">
        <color
          rgba="0.792156862745098 0.819607843137255 0.933333333333333 1" />
      </material>
    </visual>
    <collision>
      <origin
        xyz="0 0 0"
        rpy="0 0 0" />
      <geometry>
        <mesh
          filename="package://inspire_hand_description/meshes/left/link4.STL" />
      </geometry>
    </collision>
  </link>
  <joint
    name="link4"
    type="revolute">
    <origin
      xyz="-0.050841 -0.0077547 -0.08041"
      rpy="-2.0186 1.327 -2.007" />
    <parent
      link="link111" />
    <child
      link="link4" />
    <axis
      xyz="0 0 1" />
    <limit
      lower="-1.6"
      upper="0"
      effort="1"
      velocity="1" />
  </joint>
  <link
    name="link44">
    <inertial>
      <origin
        xyz="0.0155924434001128 0.00555617869155978 -1.05483765444614E-07"
        rpy="0 0 0" />
      <mass
        value="0.00356888715893842" />
      <inertia
        ixx="6.67772840408144E-08"
        ixy="-2.70391833548355E-08"
        ixz="-3.26434716125092E-12"
        iyy="4.33419425101179E-07"
        iyz="-9.18888508148905E-13"
        izz="4.39763878420807E-07" />
    </inertial>
    <visual>
      <origin
        xyz="0 0 0"
        rpy="0 0 0" />
      <geometry>
        <mesh
          filename="package://inspire_hand_description/meshes/left/link44.STL" />
      </geometry>
      <material
        name="">
        <color
          rgba="1 1 1 1" />
      </material>
    </visual>
    <collision>
      <origin
        xyz="0 0 0"
        rpy="0 0 0" />
      <geometry>
        <mesh
          filename="package://inspire_hand_description/meshes/left/link44.STL" />
      </geometry>
    </collision>
  </link>
  <joint
    name="link44"
    type="revolute">
    <origin
      xyz="0.032132 0 0"
      rpy="-5.1334E-10 -9.3483E-11 -0.18013" />
    <parent
      link="link4" />
    <child
      link="link44" />
    <axis
      xyz="0 0 1" />
    <limit
      lower="-1.7"
      upper="0"
      effort="1"
      velocity="1" />
  </joint>
  <link
    name="link5">
    <inertial>
      <origin
        xyz="-0.00433166459951286 0.000656790554769388 -0.000486675184306562"
        rpy="0 0 0" />
      <mass
        value="0.00487393910083768" />
      <inertia
        ixx="1.30409345970056E-07"
        ixy="8.91998160729811E-09"
        ixz="1.76607007575074E-08"
        iyy="1.7058032498292E-07"
        iyz="-1.02771404037179E-09"
        izz="2.11710622768954E-07" />
    </inertial>
    <visual>
      <origin
        xyz="0 0 0"
        rpy="0 0 0" />
      <geometry>
        <mesh
          filename="package://inspire_hand_description/meshes/left/link5.STL" />
      </geometry>
      <material
        name="">
        <color
          rgba="0.827450980392157 0.83921568627451 0.827450980392157 1" />
      </material>
    </visual>
    <collision>
      <origin
        xyz="0 0 0"
        rpy="0 0 0" />
      <geometry>
        <mesh
          filename="package://inspire_hand_description/meshes/left/link5.STL" />
      </geometry>
    </collision>
  </link>
  <joint
    name="link5"
    type="revolute">
    <origin
      xyz="0.0010638 -0.025 -0.0059231"
      rpy="-1.5708 -2.455E-15 2.3555" />
    <parent
      link="link111" />
    <child
      link="link5" />
    <axis
      xyz="0 -1 0" />
    <limit
      lower="-1.0"
      upper="0.3"
      effort="1"
      velocity="1" />
  </joint>
  <link
    name="link51">
    <inertial>
      <origin
        xyz="0.0261736471642429 0.00353664240332538 -7.35522423800372E-08"
        rpy="0 0 0" />
      <mass
        value="0.00652741708580189" />
      <inertia
        ixx="8.93663478287007E-07"
        ixy="6.28882108303181E-08"
        ixz="-3.67789097092471E-11"
        iyy="2.37350868720489E-06"
        iyz="8.30149702319962E-12"
        izz="2.7502170955408E-06" />
    </inertial>
    <visual>
      <origin
        xyz="0 0 0"
        rpy="0 0 0" />
      <geometry>
        <mesh
          filename="package://inspire_hand_description/meshes/left/link51.STL" />
      </geometry>
      <material
        name="">
        <color
          rgba="0.792156862745098 0.819607843137255 0.933333333333333 1" />
      </material>
    </visual>
    <collision>
      <origin
        xyz="0 0 0"
        rpy="0 0 0" />
      <geometry>
        <mesh
          filename="package://inspire_hand_description/meshes/left/link51.STL" />
      </geometry>
    </collision>
  </link>
  <joint
    name="link51"
    type="revolute">
    <origin
      xyz="-0.0115 -0.00075 0"
      rpy="-1.4988E-15 -5.5511E-17 1.8988" />
    <parent
      link="link5" />
    <child
      link="link51" />
    <axis
      xyz="0 0 -1" />
    <limit
      lower="0"
      upper="0.4"
      effort="1"
      velocity="1" />
  </joint>
  <link
    name="link52">
    <inertial>
      <origin
        xyz="-0.00731595394729753 -0.00552216810488045 1.31327036717588E-07"
        rpy="0 0 0" />
      <mass
        value="0.00226947954597765" />
      <inertia
        ixx="1.72809908882086E-07"
        ixy="4.52296648937248E-08"
        ixz="-3.78399670014347E-12"
        iyy="2.78044490402836E-07"
        iyz="1.5225345233066E-13"
        izz="2.99628844053565E-07" />
    </inertial>
    <visual>
      <origin
        xyz="0 0 0"
        rpy="0 0 0" />
      <geometry>
        <mesh
          filename="package://inspire_hand_description/meshes/left/link52.STL" />
      </geometry>
      <material
        name="">
        <color
          rgba="0.827450980392157 0.83921568627451 0.827450980392157 1" />
      </material>
    </visual>
    <collision>
      <origin
        xyz="0 0 0"
        rpy="0 0 0" />
      <geometry>
        <mesh
          filename="package://inspire_hand_description/meshes/left/link52.STL" />
      </geometry>
    </collision>
  </link>
  <joint
    name="link52"
    type="revolute">
    <origin
      xyz="0.056001 0 0"
      rpy="-1.3323E-15 -2.7756E-17 -3.0416" />
    <parent
      link="link51" />
    <child
      link="link52" />
    <axis
      xyz="0 0 1" />
    <limit
      lower="-0.4"
      upper="0"
      effort="1"
      velocity="1" />
  </joint>
  <link
    name="link53">
    <inertial>
      <origin
        xyz="0.0104629360450728 0.00192820283562468 -3.38351464429509E-06"
        rpy="0 0 0" />
      <mass
        value="0.00330869122519449" />
      <inertia
        ixx="8.21794532311926E-08"
        ixy="1.14153196955289E-08"
        ixz="-1.49218673904795E-10"
        iyy="1.90093466236439E-07"
        iyz="3.77060351806357E-11"
        izz="1.96169077984371E-07" />
    </inertial>
    <visual>
      <origin
        xyz="0 0 0"
        rpy="0 0 0" />
      <geometry>
        <mesh
          filename="package://inspire_hand_description/meshes/left/link53.STL" />
      </geometry>
      <material
        name="">
        <color
          rgba="0.827450980392157 0.83921568627451 0.827450980392157 1" />
      </material>
    </visual>
    <collision>
      <origin
        xyz="0 0 0"
        rpy="0 0 0" />
      <geometry>
        <mesh
          filename="package://inspire_hand_description/meshes/left/link53.STL" />
      </geometry>
    </collision>
  </link>
  <joint
    name="link53"
    type="revolute">
    <origin
      xyz="-0.022653 0 0"
      rpy="1.2712E-14 -9.7145E-17 2.856" />
    <parent
      link="link52" />
    <child
      link="link53" />
    <axis
      xyz="0 0 1" />
    <limit
      lower="-1"
      upper="0"
      effort="1"
      velocity="1" />
  </joint>
<!-- above is the part of LEFT HAND -->  


<!-- RIGHT HAND part-->
<joint name="yumi_link_7_r_joint" type="fixed">
    <parent link="yumi_link_7_r" />
    <child link="right_hand_base" />
    <origin rpy="0 0 3.1415" xyz="0 0 0"/>
</joint>

  <!-- Create a new base frame for convenience, by LYW, 2019/11/18 -->
  <link name="right_hand_base">
    <!-- Add visual tag for calibration -->
    <!--visual>
      <origin xyz="0 0 -0.025" rpy="0 0 0" />
      <geometry>
        <cylinder radius="0.0279" length="0.05" /> <!- - diameter is 55.8 mm according to the technical specifics- ->
      </geometry>
    </visual-->
  </link>

  <!-- Fix frame of reference through solidworks measurement and manual calibration, by LYW, 2019/11/18 -->
  <joint name="Link111_shift" type="fixed">
    <origin xyz="-0.00850 0.0180 0.0404" rpy="1.5707 -1.5707 0" /> <!--0.00985 0.02039 0.0404-->
    <parent link="right_hand_base" />
    <child link="Link111" />
  </joint>

  <link
    name="Link111">
    <inertial>
      <origin
        xyz="0.0284046972660885 -0.00981060404810299 0.0222000386975785"
        rpy="0 0 0" />
      <mass
        value="0.22621959250221" />
      <inertia
        ixx="0.000161057742168925"
        ixy="-3.93039257205975E-06"
        ixz="-2.59552833985103E-06"
        iyy="0.000358621491446785"
        iyz="4.70540238948447E-06"
        izz="0.000257940666810454" />
    </inertial>
    <visual>
      <origin
        xyz="0 0 0"
        rpy="0 0 0" />
      <geometry>
        <mesh
          filename="package://inspire_hand_description/meshes/right/Link111.STL" />
      </geometry>
      <material
        name="">
        <color
          rgba="0.827450980392157 0.83921568627451 0.827450980392157 1" />
      </material>
    </visual>
    <collision>
      <origin
        xyz="0 0 0"
        rpy="0 0 0" />
      <geometry>
        <mesh
          filename="package://inspire_hand_description/meshes/right/Link111.STL" />
      </geometry>
    </collision>
  </link>
  <link
    name="Link1">
    <inertial>
      <origin
        xyz="0.0107729817589723 0.00213781834563882 -1.34009238303423E-07"
        rpy="0 0 0" />
      <mass
        value="0.00330620599604871" />
      <inertia
        ixx="1.55837657646135E-07"
        ixy="-3.78958094877833E-08"
        ixz="-5.07264353075226E-12"
        iyy="5.30383928507338E-07"
        iyz="-1.43523102869642E-12"
        izz="5.55164105212297E-07" />
    </inertial>
    <visual>
      <origin
        xyz="0 0 0"
        rpy="0 0 0" />
      <geometry>
        <mesh
          filename="package://inspire_hand_description/meshes/right/Link1.STL" />
      </geometry>
      <material
        name="">
        <color
          rgba="0.792156862745098 0.819607843137255 0.933333333333333 1" />
      </material>
    </visual>
    <collision>
      <origin
        xyz="0 0 0"
        rpy="0 0 0" />
      <geometry>
        <mesh
          filename="package://inspire_hand_description/meshes/right/Link1.STL" />
      </geometry>
    </collision>
  </link>
  <joint
    name="Link1"
    type="revolute">
    <origin
      xyz="0.08225 -0.0077547 -0.0040172"
      rpy="5.2178E-10 -6.245E-17 -0.14966" />
    <parent
      link="Link111" />
    <child
      link="Link1" />
    <axis
      xyz="0 0 1" />
    <limit
      lower="-1.6"
      upper="0"
      effort="1"
      velocity="1" />
  </joint>
  <link
    name="Link11">
    <inertial>
      <origin
        xyz="0.019017916514892 0.00563447754295066 1.90796464460963E-08"
        rpy="0 0 0" />
      <mass
        value="0.00453366822308025" />
      <inertia
        ixx="8.56969764665792E-08"
        ixy="-3.65502775787085E-08"
        ixz="2.02841411241907E-12"
        iyy="7.58232170757561E-07"
        iyz="6.07603435089188E-13"
        izz="7.68830975890361E-07" />
    </inertial>
    <visual>
      <origin
        xyz="0 0 0"
        rpy="0 0 0" />
      <geometry>
        <mesh
          filename="package://inspire_hand_description/meshes/right/Link11.STL" />
      </geometry>
      <material
        name="">
        <color
          rgba="1 1 1 1" />
      </material>
    </visual>
    <collision>
      <origin
        xyz="0 0 0"
        rpy="0 0 0" />
      <geometry>
        <mesh
          filename="package://inspire_hand_description/meshes/right/Link11.STL" />
      </geometry>
    </collision>
  </link>
  <joint
    name="Link11"
    type="revolute">
    <origin
      xyz="0.032132 0 0"
      rpy="-5.086E-10 -1.1653E-10 -0.22524" />
    <parent
      link="Link1" />
    <child
      link="Link11" />
    <axis
      xyz="0 0 1" />
    <limit
      lower="-1.7"
      upper="0"
      effort="1"
      velocity="1" />
  </joint>
  <link
    name="Link2">
    <inertial>
      <origin
        xyz="0.0107729781873397 0.00213783567195037 -1.14076048385314E-07"
        rpy="0 0 0" />
      <mass
        value="0.00330621565435093" />
      <inertia
        ixx="1.55837752420093E-07"
        ixy="-3.78955767951184E-08"
        ixz="-4.51740252002264E-12"
        iyy="5.30384784494186E-07"
        iyz="-1.08751322448059E-12"
        izz="5.55164342998361E-07" />
    </inertial>
    <visual>
      <origin
        xyz="0 0 0"
        rpy="0 0 0" />
      <geometry>
        <mesh
          filename="package://inspire_hand_description/meshes/right/Link2.STL" />
      </geometry>
      <material
        name="">
        <color
          rgba="0.792156862745098 0.819607843137255 0.933333333333333 1" />
      </material>
    </visual>
    <collision>
      <origin
        xyz="0 0 0"
        rpy="0 0 0" />
      <geometry>
        <mesh
          filename="package://inspire_hand_description/meshes/right/Link2.STL" />
      </geometry>
    </collision>
  </link>
  <joint
    name="Link2"
    type="revolute">
    <origin
      xyz="0.081939 -0.0077547 0.015305"
      rpy="0.0056158 -0.034452 -0.16161" />
    <parent
      link="Link111" />
    <child
      link="Link2" />
    <axis
      xyz="0 0 1" />
    <limit
      lower="-1.6"
      upper="0"
      effort="1"
      velocity="1" />
  </joint>
  <link
    name="Link22">
    <inertial>
      <origin
        xyz="0.0190179451505274 0.00563447968575673 1.97663586783137E-08"
        rpy="0 0 0" />
      <mass
        value="0.00453367017295165" />
      <inertia
        ixx="8.5696963969299E-08"
        ixy="-3.6550923619766E-08"
        ixz="1.59786933213099E-12"
        iyy="7.58233066456215E-07"
        iyz="6.81108952684927E-13"
        izz="7.68832070821997E-07" />
    </inertial>
    <visual>
      <origin
        xyz="0 0 0"
        rpy="0 0 0" />
      <geometry>
        <mesh
          filename="package://inspire_hand_description/meshes/right/Link22.STL" />
      </geometry>
      <material
        name="">
        <color
          rgba="1 1 1 1" />
      </material>
    </visual>
    <collision>
      <origin
        xyz="0 0 0"
        rpy="0 0 0" />
      <geometry>
        <mesh
          filename="package://inspire_hand_description/meshes/right/Link22.STL" />
      </geometry>
    </collision>
  </link>
  <joint
    name="Link22"
    type="revolute">
    <origin
      xyz="0.032132 0 0"
      rpy="-5.0853E-10 -1.1686E-10 -0.22588" />
    <parent
      link="Link2" />
    <child
      link="Link22" />
    <axis
      xyz="0 0 1" />
    <limit
      lower="-1.7"
      upper="0"
      effort="1"
      velocity="1" />
  </joint>
  <link
    name="Link3">
    <inertial>
      <origin
        xyz="0.0107730930654459 0.00213783260244832 -8.57328914740003E-08"
        rpy="0 0 0" />
      <mass
        value="0.0033061482917439" />
      <inertia
        ixx="1.55835970052989E-07"
        ixy="-3.78956285985318E-08"
        ixz="-3.98553229256186E-12"
        iyy="5.30379079243718E-07"
        iyz="-6.32137439938121E-13"
        izz="5.5516012983777E-07" />
    </inertial>
    <visual>
      <origin
        xyz="0 0 0"
        rpy="0 0 0" />
      <geometry>
        <mesh
          filename="package://inspire_hand_description/meshes/right/Link3.STL" />
      </geometry>
      <material
        name="">
        <color
          rgba="0.792156862745098 0.819607843137255 0.933333333333333 1" />
      </material>
    </visual>
    <collision>
      <origin
        xyz="0 0 0"
        rpy="0 0 0" />
      <geometry>
        <mesh
          filename="package://inspire_hand_description/meshes/right/Link3.STL" />
      </geometry>
    </collision>
  </link>
  <joint
    name="Link3"
    type="revolute">
    <origin
      xyz="0.080765 -0.0077547 0.034505"
      rpy="0.010408 -0.086645 -0.11971" />
    <parent
      link="Link111" />
    <child
      link="Link3" />
    <axis
      xyz="0 0 1" />
    <limit
      lower="-1.6"
      upper="0"
      effort="1"
      velocity="1" />
  </joint>
  <link
    name="Link33">
    <inertial>
      <origin
        xyz="0.01901789870244 0.00563447090562313 1.70050325960271E-08"
        rpy="0 0 0" />
      <mass
        value="0.00453366652527048" />
      <inertia
        ixx="8.56969335058099E-08"
        ixy="-3.65501984156752E-08"
        ixz="1.30339239962579E-12"
        iyy="7.58232117591424E-07"
        iyz="7.47249892192207E-13"
        izz="7.68830949295352E-07" />
    </inertial>
    <visual>
      <origin
        xyz="0 0 0"
        rpy="0 0 0" />
      <geometry>
        <mesh
          filename="package://inspire_hand_description/meshes/right/Link33.STL" />
      </geometry>
      <material
        name="">
        <color
          rgba="1 1 1 1" />
      </material>
    </visual>
    <collision>
      <origin
        xyz="0 0 0"
        rpy="0 0 0" />
      <geometry>
        <mesh
          filename="package://inspire_hand_description/meshes/right/Link33.STL" />
      </geometry>
    </collision>
  </link>
  <joint
    name="Link33"
    type="revolute">
    <origin
      xyz="0.032132 0 0"
      rpy="-5.0314E-10 -1.3824E-10 -0.26815" />
    <parent
      link="Link3" />
    <child
      link="Link33" />
    <axis
      xyz="0 0 1" />
    <limit
      lower="-1.7"
      upper="0"
      effort="1"
      velocity="1" />
  </joint>
  <link
    name="Link4">
    <inertial>
      <origin
        xyz="0.0107729931213964 0.00213782731321216 -7.95186542376647E-08"
        rpy="0 0 0" />
      <mass
        value="0.00330620800050046" />
      <inertia
        ixx="1.55837389573248E-07"
        ixy="-3.78958987950181E-08"
        ixz="-3.73884747536307E-12"
        iyy="5.30384597648764E-07"
        iyz="-3.63224479792676E-13"
        izz="5.55163794949727E-07" />
    </inertial>
    <visual>
      <origin
        xyz="0 0 0"
        rpy="0 0 0" />
      <geometry>
        <mesh
          filename="package://inspire_hand_description/meshes/right/Link4.STL" />
      </geometry>
      <material
        name="">
        <color
          rgba="0.792156862745098 0.819607843137255 0.933333333333333 1" />
      </material>
    </visual>
    <collision>
      <origin
        xyz="0 0 0"
        rpy="0 0 0" />
      <geometry>
        <mesh
          filename="package://inspire_hand_description/meshes/right/Link4.STL" />
      </geometry>
    </collision>
  </link>
  <joint
    name="Link4"
    type="revolute">
    <origin
      xyz="0.078587 -0.0077547 0.053617"
      rpy="0.022524 -0.13781 -0.16255" />
    <parent
      link="Link111" />
    <child
      link="Link4" />
    <axis
      xyz="0 0 1" />
    <limit
      lower="-1.6"
      upper="0"
      effort="1"
      velocity="1" />
  </joint>
  <link
    name="Link44">
    <inertial>
      <origin
        xyz="0.0155924853997512 0.00555619186912998 -1.21775195708468E-07"
        rpy="0 0 0" />
      <mass
        value="0.00356886192445218" />
      <inertia
        ixx="6.67767175628229E-08"
        ixy="-2.70385196277176E-08"
        ixz="-4.60032318294332E-12"
        iyy="4.33416353432936E-07"
        iyz="-1.36538016248102E-12"
        izz="4.39760949009649E-07" />
    </inertial>
    <visual>
      <origin
        xyz="0 0 0"
        rpy="0 0 0" />
      <geometry>
        <mesh
          filename="package://inspire_hand_description/meshes/right/Link44.STL" />
      </geometry>
      <material
        name="">
        <color
          rgba="1 1 1 1" />
      </material>
    </visual>
    <collision>
      <origin
        xyz="0 0 0"
        rpy="0 0 0" />
      <geometry>
        <mesh
          filename="package://inspire_hand_description/meshes/right/Link44.STL" />
      </geometry>
    </collision>
  </link>
  <joint
    name="Link44"
    type="revolute">
    <origin
      xyz="0.032132 0 0"
      rpy="-5.0686E-10 -1.2389E-10 -0.23972" />
    <parent
      link="Link4" />
    <child
      link="Link44" />
    <axis
      xyz="0 0 1" />
    <limit
      lower="-1.7"
      upper="0"
      effort="1"
      velocity="1" />
  </joint>
  <link
    name="Link5">
    <inertial>
      <origin
        xyz="-0.000668287872925624 -0.00209320996353089 0.0037633441647693"
        rpy="0 0 0" />
      <mass
        value="0.00487390663164139" />
      <inertia
        ixx="1.30408513803687E-07"
        ixy="-8.92030281859617E-09"
        ixz="-1.7660325194859E-08"
        iyy="1.70578986810531E-07"
        iyz="-1.02749399337787E-09"
        izz="2.1170907785655E-07" />
    </inertial>
    <visual>
      <origin
        xyz="0 0 0"
        rpy="0 0 0" />
      <geometry>
        <mesh
          filename="package://inspire_hand_description/meshes/right/Link5.STL" />
      </geometry>
      <material
        name="">
        <color
          rgba="0.827450980392157 0.83921568627451 0.827450980392157 1" />
      </material>
    </visual>
    <collision>
      <origin
        xyz="0 0 0"
        rpy="0 0 0" />
      <geometry>
        <mesh
          filename="package://inspire_hand_description/meshes/right/Link5.STL" />
      </geometry>
    </collision>
  </link>
  <joint
    name="Link5"
    type="revolute">
    <origin
      xyz="0.0089225 -0.022949 -0.00699"
      rpy="0.092365 1.1827 -1.4853" />
    <parent
      link="Link111" />
    <child
      link="Link5" />
    <axis
      xyz="0 1 0" />
    <limit
      lower="-1"
      upper="0.3"
      effort="1"
      velocity="1" />
  </joint>
  <link
    name="Link51">
    <inertial>
      <origin
        xyz="0.0261732090129406 0.00353701767650547 -1.92601341111875E-07"
        rpy="0 0 0" />
      <mass
        value="0.00652729219675812" />
      <inertia
        ixx="8.93817123585481E-07"
        ixy="6.28368840765271E-08"
        ixz="-2.00458419649248E-11"
        iyy="2.37370603240555E-06"
        iyz="-1.67466441559282E-12"
        izz="2.75021956933668E-06" />
    </inertial>
    <visual>
      <origin
        xyz="0 0 0"
        rpy="0 0 0" />
      <geometry>
        <mesh
          filename="package://inspire_hand_description/meshes/right/Link51.STL" />
      </geometry>
      <material
        name="">
        <color
          rgba="0.792156862745098 0.819607843137255 0.933333333333333 1" />
      </material>
    </visual>
    <collision>
      <origin
        xyz="0 0 0"
        rpy="0 0 0" />
      <geometry>
        <mesh
          filename="package://inspire_hand_description/meshes/right/Link51.STL" />
      </geometry>
    </collision>
  </link>
  <joint
    name="Link51"
    type="revolute">
    <origin
      xyz="0.0065 -0.0035 0.00425"
      rpy="3.1416 -5.2736E-16 0.96726" />
    <parent
      link="Link5" />
    <child
      link="Link51" />
    <axis
      xyz="0 0 -1" />
    <limit
      lower="0"
      upper="0.4"
      effort="1"
      velocity="1" />
  </joint>
  <link
    name="Link52">
    <inertial>
      <origin
        xyz="-0.007316119869056 -0.00552223433089214 2.14610152510231E-07"
        rpy="0 0 0" />
      <mass
        value="0.0022695308360543" />
      <inertia
        ixx="1.7281059843115E-07"
        ixy="4.52282139518593E-08"
        ixz="-2.88816078436063E-12"
        iyy="2.78046552011382E-07"
        iyz="7.05843881266438E-13"
        izz="2.99630657437474E-07" />
    </inertial>
    <visual>
      <origin
        xyz="0 0 0"
        rpy="0 0 0" />
      <geometry>
        <mesh
          filename="package://inspire_hand_description/meshes/right/Link52.STL" />
      </geometry>
      <material
        name="">
        <color
          rgba="0.827450980392157 0.83921568627451 0.827450980392157 1" />
      </material>
    </visual>
    <collision>
      <origin
        xyz="0 0 0"
        rpy="0 0 0" />
      <geometry>
        <mesh
          filename="package://inspire_hand_description/meshes/right/Link52.STL" />
      </geometry>
    </collision>
  </link>
  <joint
    name="Link52"
    type="revolute">
    <origin
      xyz="0.056001 0 0"
      rpy="0 -1.3878E-16 2.9661" />
    <parent
      link="Link51" />
    <child
      link="Link52" />
    <axis
      xyz="0 0 1" />
    <limit
      lower="-0.4"
      upper="0"
      effort="1"
      velocity="1" />
  </joint>
  <link
    name="Link53">
    <inertial>
      <origin
        xyz="-3.3937612879259E-06 0.0106230303829815 0.000584861433263272"
        rpy="0 0 0" />
      <mass
        value="0.00330869751403717" />
      <inertia
        ixx="1.96169236089202E-07"
        ixy="-1.43223823727531E-10"
        ixz="5.64113109591019E-11"
        iyy="8.67914197835909E-08"
        iyz="2.46315104630635E-08"
        izz="1.85481756939709E-07" />
    </inertial>
    <visual>
      <origin
        xyz="0 0 0"
        rpy="0 0 0" />
      <geometry>
        <mesh
          filename="package://inspire_hand_description/meshes/right/Link53.STL" />
      </geometry>
      <material
        name="">
        <color
          rgba="0.827450980392157 0.83921568627451 0.827450980392157 1" />
      </material>
    </visual>
    <collision>
      <origin
        xyz="0 0 0"
        rpy="0 0 0" />
      <geometry>
        <mesh
          filename="package://inspire_hand_description/meshes/right/Link53.STL" />
      </geometry>
    </collision>
  </link>
  <joint
    name="Link53"
    type="revolute">
    <origin
      xyz="-0.022653 0 0"
      rpy="1.7291 -1.5708 0" />
    <parent
      link="Link52" />
    <child
      link="Link53" />
    <axis
      xyz="1 0 0" />
    <limit
      lower="-1"
      upper="0"
      effort="1"
      velocity="1" />
  </joint>
  
<!-- above is the part of RIGHT HAND -->  


  <!-- Trans for RIGHT HAND-->
  <transmission name="Link1_trans">
    <type>transmission_interface/SimpleTransmission</type>
    <joint name="Link1">
      <hardwareInterface>hardware_interface/PositionJointInterface</hardwareInterface>
    </joint>
    <actuator name="Link1_motor">
      <hardwareInterface>hardware_interface/PositionJointInterface</hardwareInterface>
      <mechanicalReduction>1</mechanicalReduction>
    </actuator>
  </transmission>

  <transmission name="Link11_trans">
    <type>transmission_interface/SimpleTransmission</type>
    <joint name="Link11">
      <hardwareInterface>hardware_interface/PositionJointInterface</hardwareInterface>
    </joint>
    <actuator name="Link11_motor">
      <hardwareInterface>hardware_interface/PositionJointInterface</hardwareInterface>
      <mechanicalReduction>1</mechanicalReduction>
    </actuator>
  </transmission>

  <transmission name="Link2_trans">
    <type>transmission_interface/SimpleTransmission</type>
    <joint name="Link2">
      <hardwareInterface>hardware_interface/PositionJointInterface</hardwareInterface>
    </joint>
    <actuator name="Link2_motor">
      <hardwareInterface>hardware_interface/PositionJointInterface</hardwareInterface>
      <mechanicalReduction>1</mechanicalReduction>
    </actuator>
  </transmission>

  <transmission name="Link22_trans">
    <type>transmission_interface/SimpleTransmission</type>
    <joint name="Link22">
      <hardwareInterface>hardware_interface/PositionJointInterface</hardwareInterface>
    </joint>
    <actuator name="Link22_motor">
      <hardwareInterface>hardware_interface/PositionJointInterface</hardwareInterface>
      <mechanicalReduction>1</mechanicalReduction>
    </actuator>
  </transmission>

  <transmission name="Link3_trans">
    <type>transmission_interface/SimpleTransmission</type>
    <joint name="Link3">
      <hardwareInterface>hardware_interface/PositionJointInterface</hardwareInterface>
    </joint>
    <actuator name="Link3_motor">
      <hardwareInterface>hardware_interface/PositionJointInterface</hardwareInterface>
      <mechanicalReduction>1</mechanicalReduction>
    </actuator>
  </transmission>

  <transmission name="Link33_trans">
    <type>transmission_interface/SimpleTransmission</type>
    <joint name="Link33">
      <hardwareInterface>hardware_interface/PositionJointInterface</hardwareInterface>
    </joint>
    <actuator name="Link33_motor">
      <hardwareInterface>hardware_interface/PositionJointInterface</hardwareInterface>
      <mechanicalReduction>1</mechanicalReduction>
    </actuator>
  </transmission>

  <transmission name="Link4_trans">
    <type>transmission_interface/SimpleTransmission</type>
    <joint name="Link4">
      <hardwareInterface>hardware_interface/PositionJointInterface</hardwareInterface>
    </joint>
    <actuator name="Link4_motor">
      <hardwareInterface>hardware_interface/PositionJointInterface</hardwareInterface>
      <mechanicalReduction>1</mechanicalReduction>
    </actuator>
  </transmission>

  <transmission name="Link44_trans">
    <type>transmission_interface/SimpleTransmission</type>
    <joint name="Link44">
      <hardwareInterface>hardware_interface/PositionJointInterface</hardwareInterface>
    </joint>
    <actuator name="Link44_motor">
      <hardwareInterface>hardware_interface/PositionJointInterface</hardwareInterface>
      <mechanicalReduction>1</mechanicalReduction>
    </actuator>
  </transmission>

  <transmission name="Link5_trans">
    <type>transmission_interface/SimpleTransmission</type>
    <joint name="Link5">
      <hardwareInterface>hardware_interface/PositionJointInterface</hardwareInterface>
    </joint>
    <actuator name="Link5_motor">
      <hardwareInterface>hardware_interface/PositionJointInterface</hardwareInterface>
      <mechanicalReduction>1</mechanicalReduction>
    </actuator>
  </transmission>

  <transmission name="Link51_trans">
    <type>transmission_interface/SimpleTransmission</type>
    <joint name="Link51">
      <hardwareInterface>hardware_interface/PositionJointInterface</hardwareInterface>
    </joint>
    <actuator name="Link51_motor">
      <hardwareInterface>hardware_interface/PositionJointInterface</hardwareInterface>
      <mechanicalReduction>1</mechanicalReduction>
    </actuator>
  </transmission>

  <transmission name="Link52_trans">
    <type>transmission_interface/SimpleTransmission</type>
    <joint name="Link52">
      <hardwareInterface>hardware_interface/PositionJointInterface</hardwareInterface>
    </joint>
    <actuator name="Link52_motor">
      <hardwareInterface>hardware_interface/PositionJointInterface</hardwareInterface>
      <mechanicalReduction>1</mechanicalReduction>
    </actuator>
  </transmission>

  <transmission name="Link53_trans">
    <type>transmission_interface/SimpleTransmission</type>
    <joint name="Link53">
      <hardwareInterface>hardware_interface/PositionJointInterface</hardwareInterface>
    </joint>
    <actuator name="Link53_motor">
      <hardwareInterface>hardware_interface/PositionJointInterface</hardwareInterface>
      <mechanicalReduction>1</mechanicalReduction>
    </actuator>
  </transmission>

  <!-- above is the part of TRANSMISSION FOR BOTH HANDS--> 


</robot>
