<robot xmlns:xacro="http://www.ros.org/wiki/xacro"
xmlns:sensor="http://playerstage.sourceforge.net/gazebo/xmlschema/#sensor"
xmlns:controller="http://playerstage.sourceforge.net/gazebo/xmlschema/#controller"
xmlns:joint="http://playerstage.sourceforge.net/gazebo/xmlschema/#slider"
xmlns:interface="http://playerstage.sourceforge.net/gazebo/xmlschema/#interface"
xmlns:body="http://playerstage.sourceforge.net/gazebo/xmlschema/#body"
xmlns:geom="http://playerstage.sourceforge.net/gazebo/xmlschema/#geom">

  <xacro:include filename="$(find sr_description)/hand/xacro/finger/middle/middle.gazebo.xacro" />
  <xacro:include filename="$(find sr_description)/hand/xacro/finger/middle/middle.transmission.xacro" />
  <!-- muscle is true for muscle hand or false for motor hand -->
  <!-- prefix can be anything but usually is "r_" or  "l_" for right and left hands distinction -->
  <!-- link_prefix prepends fingername to the link names -->
  <!-- joint_prefix prepends fingername to the joint names -->
  <!-- parent is the parent link for the joint -->
  <xacro:macro name="middle"
  params="muscle prefix link_prefix joint_prefix parent">
    <link name="${prefix}${link_prefix}middle">
      <inertial>
        <origin xyz="0 0 0.0125" rpy="0 0 0" />
        <mass value="0.017" />
        <inertia ixx="0.0000026" ixy="0.0" ixz="0.0"
        iyy="0.0000027" iyz="0.0" izz="0.00000087" />
      </inertial>
      <visual>
        <origin xyz="0 0 0" rpy="0 0 0" />
        <geometry name="${prefix}${link_prefix}middle_visual">
          <mesh filename="package://sr_description/meshes/hand/F2.dae"
          scale="0.001 0.001 0.001" />
        </geometry>
        <material name="Grey" />
      </visual>
      <collision>
        <origin xyz="0 0 0.0125" rpy="0 0 0" />
        <geometry name="${prefix}${link_prefix}middle_collision_geom">

          <cylinder radius="0.007" length="0.025" />
        </geometry>
      </collision>
      <collision>
        <origin xyz="0 0 0.0" rpy="0 0 0" />
        <geometry>
          <sphere radius="0.007" />
        </geometry>
      </collision>
      <collision>
        <origin xyz="0 0 0.025" rpy="0 0 0" />
        <geometry>
          <sphere radius="0.007" />
        </geometry>
      </collision>
    </link>
    <joint name="${prefix}${joint_prefix}J2" type="revolute">
      <parent link="${parent}" />
      <child link="${prefix}${link_prefix}middle" />
      <origin xyz="0 0 0.045" rpy="0 0 0" />
      <axis xyz="1 0 0" />
      <limit lower="0" upper="${M_PI/2}" effort="2"
      velocity="2.0" />
      <dynamics damping="0.1" />
    </joint>
    <gazebo reference="${prefix}${joint_prefix}J2">
      <provideFeedback>1</provideFeedback>
      <implicitSpringDamper>1</implicitSpringDamper>
    </gazebo>
    <!-- extensions -->
    <xacro:middle_transmission muscletrans="${muscle}"
    prefix="${prefix}" joint_prefix="${joint_prefix}"
    link_prefix="${link_prefix}" />
    <xacro:middle_gazebo prefix="${prefix}"
    link_prefix="${link_prefix}" />
  </xacro:macro>
</robot>
