<robot xmlns:xacro="http://www.ros.org/wiki/xacro">
  <xacro:include filename="$(find sr_description)/arm/xacro/upper_arm/shadowarm_upperarm.transmission.xacro" />
  <xacro:macro name="shadowarm_upperarm" params="parent">
    <link name="shadowarm_upperarm">
      <inertial>
        <origin xyz="0 0 0.1845" rpy="0 0 0" />
        <mass value="2" />
        <inertia ixx="0.044" ixy="0.0" ixz="0.0" iyy="0.044"
        iyz="0.0" izz="0.0056" />
      </inertial>
      <visual>
        <origin xyz="0 0.067 0" rpy="0 0 0" />
        <geometry name="shadowarm_upperarm_visual">
          <mesh filename="package://sr_description/arm/model/upper_arm.dae"
          scale="0.001 0.001 0.001" />
        </geometry>
        <material name="Grey" />
      </visual>
      <collision>
        <origin xyz="0 0 0.16" rpy="0 -${M_PI} 0" />
        <geometry name="shadowarm_upperarm_collision">
          <box size="0.170 0.133 0.470" />
        </geometry>
      </collision>
    </link>
    <gazebo reference="shadowarm_upperarm">
      <selfCollide>false</selfCollide>
    </gazebo>
    <joint name="ShoulderJSwing" type="revolute">
      <parent link="${parent}" />
      <child link="shadowarm_upperarm" />
      <origin xyz="0 -0.134 0.5305" rpy="0 -${M_PI} 0.0" />
      <!-- yaw=-0.026 -->
      <axis xyz="0 -1 0" />
      <limit lower="0" upper="${M_PI/2}" effort="100"
      velocity="1.0" />
      <dynamics damping="5.3" />
    </joint>
    <gazebo reference="ShoulderJSwing">
      <provideFeedback>1</provideFeedback>
      <implicitSpringDamper>1</implicitSpringDamper>
    </gazebo>
    <xacro:shadowarm_upperarm_transmission />
  </xacro:macro>
</robot>
