<?xml version="1.0" ?>
<!-- =================================================================================== -->
<!-- |    This document was autogenerated by xacro from human_hand_model.urdf.xacro    | -->
<!-- |    EDITING THIS FILE BY HAND IS NOT RECOMMENDED                                 | -->
<!-- =================================================================================== -->
<robot name="human_hand_model" xmlns:xacro="http://wiki.ros.org/xacro">
  <!-- Palm -->
  <link name="tmp_palm">
    <visual>
      <origin rpy="0 0 0" xyz="0 0 0.075"/>
      <geometry>
        <box size="0.01 0.1 0.15"/>
      </geometry>
      <material name="LightGold">
        <color rgba="0.933 0.867 0.510 1.0"/>
      </material>
    </visual>
  </link>
  <joint name="tmp_palm_joint" type="fixed">
    <origin rpy="0 0 0" xyz="0 0 0"/>
    <parent link="not_world"/>
    <child link="tmp_palm"/>
  </joint>
  <!-- Proximal Phalange -->
  <link name="tmp_little_finger_PP_link">
    <visual>
      <origin rpy="0 0 0" xyz="0 0 0.015"/>
      <geometry>
        <box size="0.01 0.015 0.03"/>
      </geometry>
      <material name="PaleGreen">
        <color rgba="0.596 0.984 0.596 1.0"/>
      </material>
    </visual>
  </link>
  <!-- a virtual link -->
  <link name="tmp_little_finger_virtual_link"/>
  <!-- Intermediate Phalange -->
  <link name="tmp_little_finger_IP_link">
    <visual>
      <origin rpy="0 0 0" xyz="0 0 0.01"/>
      <geometry>
        <box size="0.01 0.015 0.02"/>
      </geometry>
      <material name="LightSkyBlue">
        <color rgba="0.529 0.808 0.980 1.0"/>
      </material>
    </visual>
  </link>
  <!-- Distal Phalange -->
  <link name="tmp_little_finger_DP_link">
    <visual>
      <origin rpy="0 0 0" xyz="0 0 0.005"/>
      <geometry>
        <box size="0.01 0.015 0.01"/>
      </geometry>
      <material name="LightSalmon">
        <color rgba="1.0 0.627 0.478 1.0"/>
      </material>
    </visual>
  </link>
  <!-- Metacarpophalangeal Joint, for abduction/adduction -->
  <joint name="tmp_little_finger_MCP_abduction_joint" type="revolute">
    <origin rpy="0 0 0" xyz="0.0 -0.0425 0.15"/>
    <axis xyz="1 0 0"/>
    <parent link="tmp_palm"/>
    <child link="tmp_little_finger_virtual_link"/>
    <limit effort="100" lower="-0.174532925199" upper="0.174532925199" velocity="10.0"/>
  </joint>
  <!-- Metacarpophalangeal Joint, for extension/flexion -->
  <joint name="tmp_little_finger_MCP_flexion_joint" type="revolute">
    <origin rpy="0 0 0" xyz="0 0 0"/>
    <axis xyz="0 1 0"/>
    <parent link="tmp_little_finger_virtual_link"/>
    <child link="tmp_little_finger_PP_link"/>
    <limit effort="100" lower="0" upper="1.57079632679" velocity="10.0"/>
  </joint>
  <!-- Proximal Interphalangeal Joint -->
  <joint name="tmp_little_finger_PIP_joint" type="revolute">
    <origin rpy="0 0 0" xyz="0 0 0.03"/>
    <axis xyz="0 1 0"/>
    <parent link="tmp_little_finger_PP_link"/>
    <child link="tmp_little_finger_IP_link"/>
    <limit effort="100" lower="0" upper="1.57079632679" velocity="10.0"/>
  </joint>
  <!-- Distal Interphalangeal Joint -->
  <joint name="tmp_little_finger_DIP_joint" type="revolute">
    <origin rpy="0 0 0" xyz="0 0 0.02"/>
    <axis xyz="0 1 0"/>
    <parent link="tmp_little_finger_IP_link"/>
    <child link="tmp_little_finger_DP_link"/>
    <limit effort="100" lower="0" upper="1.57079632679" velocity="10.0"/>
  </joint>
  <!-- Proximal Phalange -->
  <link name="tmp_ring_finger_PP_link">
    <visual>
      <origin rpy="0 0 0" xyz="0 0 0.02"/>
      <geometry>
        <box size="0.01 0.015 0.04"/>
      </geometry>
      <material name="PaleGreen">
        <color rgba="0.596 0.984 0.596 1.0"/>
      </material>
    </visual>
  </link>
  <!-- a virtual link -->
  <link name="tmp_ring_finger_virtual_link"/>
  <!-- Intermediate Phalange -->
  <link name="tmp_ring_finger_IP_link">
    <visual>
      <origin rpy="0 0 0" xyz="0 0 0.015"/>
      <geometry>
        <box size="0.01 0.015 0.03"/>
      </geometry>
      <material name="LightSkyBlue">
        <color rgba="0.529 0.808 0.980 1.0"/>
      </material>
    </visual>
  </link>
  <!-- Distal Phalange -->
  <link name="tmp_ring_finger_DP_link">
    <visual>
      <origin rpy="0 0 0" xyz="0 0 0.01"/>
      <geometry>
        <box size="0.01 0.015 0.02"/>
      </geometry>
      <material name="LightSalmon">
        <color rgba="1.0 0.627 0.478 1.0"/>
      </material>
    </visual>
  </link>
  <!-- Metacarpophalangeal Joint, for abduction/adduction -->
  <joint name="tmp_ring_finger_MCP_abduction_joint" type="revolute">
    <origin rpy="0 0 0" xyz="0.0 -0.0175 0.15"/>
    <axis xyz="1 0 0"/>
    <parent link="tmp_palm"/>
    <child link="tmp_ring_finger_virtual_link"/>
    <limit effort="100" lower="-0.174532925199" upper="0.174532925199" velocity="10.0"/>
  </joint>
  <!-- Metacarpophalangeal Joint, for extension/flexion -->
  <joint name="tmp_ring_finger_MCP_flexion_joint" type="revolute">
    <origin rpy="0 0 0" xyz="0 0 0"/>
    <axis xyz="0 1 0"/>
    <parent link="tmp_ring_finger_virtual_link"/>
    <child link="tmp_ring_finger_PP_link"/>
    <limit effort="100" lower="0" upper="1.57079632679" velocity="10.0"/>
  </joint>
  <!-- Proximal Interphalangeal Joint -->
  <joint name="tmp_ring_finger_PIP_joint" type="revolute">
    <origin rpy="0 0 0" xyz="0 0 0.04"/>
    <axis xyz="0 1 0"/>
    <parent link="tmp_ring_finger_PP_link"/>
    <child link="tmp_ring_finger_IP_link"/>
    <limit effort="100" lower="0" upper="1.57079632679" velocity="10.0"/>
  </joint>
  <!-- Distal Interphalangeal Joint -->
  <joint name="tmp_ring_finger_DIP_joint" type="revolute">
    <origin rpy="0 0 0" xyz="0 0 0.03"/>
    <axis xyz="0 1 0"/>
    <parent link="tmp_ring_finger_IP_link"/>
    <child link="tmp_ring_finger_DP_link"/>
    <limit effort="100" lower="0" upper="1.57079632679" velocity="10.0"/>
  </joint>
  <!-- Proximal Phalange -->
  <link name="tmp_middle_finger_PP_link">
    <visual>
      <origin rpy="0 0 0" xyz="0 0 0.0215"/>
      <geometry>
        <box size="0.01 0.015 0.043"/>
      </geometry>
      <material name="PaleGreen">
        <color rgba="0.596 0.984 0.596 1.0"/>
      </material>
    </visual>
  </link>
  <!-- a virtual link -->
  <link name="tmp_middle_finger_virtual_link"/>
  <!-- Intermediate Phalange -->
  <link name="tmp_middle_finger_IP_link">
    <visual>
      <origin rpy="0 0 0" xyz="0 0 0.016"/>
      <geometry>
        <box size="0.01 0.015 0.032"/>
      </geometry>
      <material name="LightSkyBlue">
        <color rgba="0.529 0.808 0.980 1.0"/>
      </material>
    </visual>
  </link>
  <!-- Distal Phalange -->
  <link name="tmp_middle_finger_DP_link">
    <visual>
      <origin rpy="0 0 0" xyz="0 0 0.0105"/>
      <geometry>
        <box size="0.01 0.015 0.021"/>
      </geometry>
      <material name="LightSalmon">
        <color rgba="1.0 0.627 0.478 1.0"/>
      </material>
    </visual>
  </link>
  <!-- Metacarpophalangeal Joint, for abduction/adduction -->
  <joint name="tmp_middle_finger_MCP_abduction_joint" type="revolute">
    <origin rpy="0 0 0" xyz="0.0 0.0175 0.15"/>
    <axis xyz="1 0 0"/>
    <parent link="tmp_palm"/>
    <child link="tmp_middle_finger_virtual_link"/>
    <limit effort="100" lower="-0.174532925199" upper="0.174532925199" velocity="10.0"/>
  </joint>
  <!-- Metacarpophalangeal Joint, for extension/flexion -->
  <joint name="tmp_middle_finger_MCP_flexion_joint" type="revolute">
    <origin rpy="0 0 0" xyz="0 0 0"/>
    <axis xyz="0 1 0"/>
    <parent link="tmp_middle_finger_virtual_link"/>
    <child link="tmp_middle_finger_PP_link"/>
    <limit effort="100" lower="0" upper="1.57079632679" velocity="10.0"/>
  </joint>
  <!-- Proximal Interphalangeal Joint -->
  <joint name="tmp_middle_finger_PIP_joint" type="revolute">
    <origin rpy="0 0 0" xyz="0 0 0.043"/>
    <axis xyz="0 1 0"/>
    <parent link="tmp_middle_finger_PP_link"/>
    <child link="tmp_middle_finger_IP_link"/>
    <limit effort="100" lower="0" upper="1.57079632679" velocity="10.0"/>
  </joint>
  <!-- Distal Interphalangeal Joint -->
  <joint name="tmp_middle_finger_DIP_joint" type="revolute">
    <origin rpy="0 0 0" xyz="0 0 0.032"/>
    <axis xyz="0 1 0"/>
    <parent link="tmp_middle_finger_IP_link"/>
    <child link="tmp_middle_finger_DP_link"/>
    <limit effort="100" lower="0" upper="1.57079632679" velocity="10.0"/>
  </joint>
  <!-- Proximal Phalange -->
  <link name="tmp_index_finger_PP_link">
    <visual>
      <origin rpy="0 0 0" xyz="0 0 0.02"/>
      <geometry>
        <box size="0.01 0.015 0.04"/>
      </geometry>
      <material name="PaleGreen">
        <color rgba="0.596 0.984 0.596 1.0"/>
      </material>
    </visual>
  </link>
  <!-- a virtual link -->
  <link name="tmp_index_finger_virtual_link"/>
  <!-- Intermediate Phalange -->
  <link name="tmp_index_finger_IP_link">
    <visual>
      <origin rpy="0 0 0" xyz="0 0 0.015"/>
      <geometry>
        <box size="0.01 0.015 0.03"/>
      </geometry>
      <material name="LightSkyBlue">
        <color rgba="0.529 0.808 0.980 1.0"/>
      </material>
    </visual>
  </link>
  <!-- Distal Phalange -->
  <link name="tmp_index_finger_DP_link">
    <visual>
      <origin rpy="0 0 0" xyz="0 0 0.01"/>
      <geometry>
        <box size="0.01 0.015 0.02"/>
      </geometry>
      <material name="LightSalmon">
        <color rgba="1.0 0.627 0.478 1.0"/>
      </material>
    </visual>
  </link>
  <!-- Metacarpophalangeal Joint, for abduction/adduction -->
  <joint name="tmp_index_finger_MCP_abduction_joint" type="revolute">
    <origin rpy="0 0 0" xyz="0.0 0.0425 0.15"/>
    <axis xyz="1 0 0"/>
    <parent link="tmp_palm"/>
    <child link="tmp_index_finger_virtual_link"/>
    <limit effort="100" lower="-0.174532925199" upper="0.174532925199" velocity="10.0"/>
  </joint>
  <!-- Metacarpophalangeal Joint, for extension/flexion -->
  <joint name="tmp_index_finger_MCP_flexion_joint" type="revolute">
    <origin rpy="0 0 0" xyz="0 0 0"/>
    <axis xyz="0 1 0"/>
    <parent link="tmp_index_finger_virtual_link"/>
    <child link="tmp_index_finger_PP_link"/>
    <limit effort="100" lower="0" upper="1.57079632679" velocity="10.0"/>
  </joint>
  <!-- Proximal Interphalangeal Joint -->
  <joint name="tmp_index_finger_PIP_joint" type="revolute">
    <origin rpy="0 0 0" xyz="0 0 0.04"/>
    <axis xyz="0 1 0"/>
    <parent link="tmp_index_finger_PP_link"/>
    <child link="tmp_index_finger_IP_link"/>
    <limit effort="100" lower="0" upper="1.57079632679" velocity="10.0"/>
  </joint>
  <!-- Distal Interphalangeal Joint -->
  <joint name="tmp_index_finger_DIP_joint" type="revolute">
    <origin rpy="0 0 0" xyz="0 0 0.03"/>
    <axis xyz="0 1 0"/>
    <parent link="tmp_index_finger_IP_link"/>
    <child link="tmp_index_finger_DP_link"/>
    <limit effort="100" lower="0" upper="1.57079632679" velocity="10.0"/>
  </joint>
  <!-- virtual links -->
  <link name="tmp_thumb_virtual_link_1"/>
  <link name="tmp_thumb_virtual_link_2"/>
  <!-- Proximal Phalange -->
  <link name="tmp_thumb_PP_link">
    <visual>
      <origin rpy="0 0 0" xyz="0 0 0.025"/>
      <geometry>
        <box size="0.01 0.015 0.05"/>
      </geometry>
      <material name="PaleGreen">
        <color rgba="0.596 0.984 0.596 1.0"/>
      </material>
    </visual>
  </link>
  <!-- Intermediate Phalange -->
  <link name="tmp_thumb_IP_link">
    <visual>
      <origin rpy="0 0 0" xyz="0 0 0.015"/>
      <geometry>
        <box size="0.01 0.015 0.03"/>
      </geometry>
      <material name="LightSkyBlue">
        <color rgba="0.529 0.808 0.980 1.0"/>
      </material>
    </visual>
  </link>
  <!-- Distal Phalange -->
  <link name="tmp_thumb_DP_link">
    <visual>
      <origin rpy="0 0 0" xyz="0 0 0.01"/>
      <geometry>
        <box size="0.01 0.015 0.02"/>
      </geometry>
      <material name="LightSalmon">
        <color rgba="1.0 0.627 0.478 1.0"/>
      </material>
    </visual>
  </link>
  <!-- Metacarpophalangeal Joint 1 -->
  <joint name="tmp_thumb_MCP_joint_1" type="revolute">
    <origin rpy="0 0 0" xyz="0.0 0.05 0.0"/>
    <axis xyz="-1 0 0"/>
    <parent link="tmp_palm"/>
    <child link="tmp_thumb_virtual_link_1"/>
    <limit effort="100" lower="0.0" upper="0.349065850399" velocity="10.0"/>
  </joint>
  <!-- Metacarpophalangeal Joint 2 -->
  <joint name="tmp_thumb_MCP_joint_2" type="revolute">
    <origin rpy="0 0 0" xyz="0 0 0"/>
    <axis xyz="0 0 -1"/>
    <parent link="tmp_thumb_virtual_link_1"/>
    <child link="tmp_thumb_PP_link"/>
    <limit effort="100" lower="0" upper="1.74532925199" velocity="10.0"/>
  </joint>
  <!-- Proximal Interphalangeal Joint 1 -->
  <joint name="tmp_thumb_PIP_joint_1" type="revolute">
    <origin rpy="0 0 0" xyz="0 0 0.05"/>
    <axis xyz="1 0 0"/>
    <parent link="tmp_thumb_PP_link"/>
    <child link="tmp_thumb_virtual_link_2"/>
    <limit effort="100" lower="0" upper="0.785398163397" velocity="10.0"/>
  </joint>
  <!-- Proximal Interphalangeal Joint 2 -->
  <joint name="tmp_thumb_PIP_joint_2" type="revolute">
    <origin rpy="0 0 0" xyz="0 0 0"/>
    <axis xyz="0 1 0"/>
    <parent link="tmp_thumb_virtual_link_2"/>
    <child link="tmp_thumb_IP_link"/>
    <limit effort="100" lower="0" upper="1.57079632679" velocity="10.0"/>
  </joint>
  <!-- Distal Interphalangeal Joint -->
  <joint name="tmp_thumb_DIP_joint" type="revolute">
    <origin rpy="0 0 0" xyz="0 0 0.03"/>
    <axis xyz="0 1 0"/>
    <parent link="tmp_thumb_IP_link"/>
    <child link="tmp_thumb_DP_link"/>
    <limit effort="100" lower="0" upper="1.57079632679" velocity="10.0"/>
  </joint>
</robot>

