<robot xmlns:xacro="http://www.ros.org/wiki/xacro"
xmlns:sensor="http://playerstage.sourceforge.net/gazebo/xmlschema/#sensor"
xmlns:controller="http://playerstage.sourceforge.net/gazebo/xmlschema/#controller"
xmlns:joint="http://playerstage.sourceforge.net/gazebo/xmlschema/#slider"
xmlns:interface="http://playerstage.sourceforge.net/gazebo/xmlschema/#interface"
xmlns:body="http://playerstage.sourceforge.net/gazebo/xmlschema/#body"
xmlns:geom="http://playerstage.sourceforge.net/gazebo/xmlschema/#geom">

  <xacro:include filename="$(find sr_description)/hand/xacro/finger/lfmetacarpal/lfmetacarpal.gazebo.xacro" />
  <xacro:include filename="$(find sr_description)/hand/xacro/finger/lfmetacarpal/lfmetacarpal.transmission.xacro" />
  <!-- muscle is true for muscle hand or false for motor hand -->
  <!-- prefix can be anything but usually is "r_" or  "l_" for right and left hands distinction -->
  <!-- reflect is either 1 (for right hand) or -1 (for left hand) -->
  <!-- parent is the parent link for the joint -->
  <xacro:macro name="lfmetacarpal"
  params="muscle prefix reflect parent">
    <link name="${prefix}lfmetacarpal">
      <inertial>
        <origin xyz="0 0 0.04" rpy="0 0 0" />
        <mass value="0.030" />
        <inertia ixx="0.0000145" ixy="0.0" ixz="0.0"
        iyy="0.00001638" iyz="0.0" izz="0.000004272" />
      </inertial>
      <visual>
        <origin xyz="0 0 0" rpy="0 0 0" />
        <geometry name="${prefix}lfmetacarpal_visual">
          <mesh filename="package://sr_description/meshes/hand/lfmetacarpal.dae"
          scale="${reflect*0.001} 0.001 0.001" />
        </geometry>
        <material name="Grey" />
      </visual>
      <collision>
        <origin xyz="0 0 0.038" rpy="0 0 0" />
        <geometry name="${prefix}lfmetacarpal_collision_geom">
          <box size="0.018 0.024 0.040" />
        </geometry>
      </collision>
    </link>
    <joint name="${prefix}LFJ5" type="revolute">
      <parent link="${parent}" />
      <child link="${prefix}lfmetacarpal" />
      <origin xyz="${reflect*-0.033} 0 0.02071" rpy="0 0 0" />
      <axis xyz="0.573576436 0 ${reflect*0.819152044}" />
      <limit lower="0" upper="${45/180*M_PI}" effort="2"
      velocity="2.0" />
      <dynamics damping="0.1" />
    </joint>
    <gazebo reference="${prefix}LFJ5">
      <provideFeedback>1</provideFeedback>
      <implicitSpringDamper>1</implicitSpringDamper>
    </gazebo>
    <!-- extensions -->
    <xacro:lfmetacarpal_transmission muscletrans="${muscle}"
    prefix="${prefix}" />
    <xacro:lfmetacarpal_gazebo prefix="${prefix}"
    link_prefix="${link_prefix}" />
  </xacro:macro>
</robot>
