<?xml version="1.0" ?>
<!-- =================================================================================== -->
<!-- |    This document was autogenerated by xacro from human_model.urdf.xacro         | -->
<!-- |    EDITING THIS FILE BY HAND IS NOT RECOMMENDED                                 | -->
<!-- =================================================================================== -->
<robot name="human_model" xmlns:xacro="http://www.ros.org/wiki/xacro">
  <gazebo>
    <plugin filename="libgazebo_ros_control.so" name="gazebo_ros_control">
      <robotNamespace>/</robotNamespace>
      <robotSimType>gazebo_ros_control/DefaultRobotHWSim</robotSimType>
      <legacyModeNS>true</legacyModeNS>
    </plugin>
  </gazebo>
  <!-- The arm should be attached to world frame, 
     and the shoulder position should be specified by (x,y,z)
     via three prismatic joints.
-->
  <param name="pi" value="3.14159"/>
  <!-- World link-->
  <link name="world"/>
  <!-- Human model base -->
  <link name="human_base_link">
    <inertial>
      <origin rpy="0 0 0" xyz="0 0 0"/>
      <mass value="1"/>
      <inertia ixx="1.0" ixy="0.0" ixz="0.0" iyy="1.0" iyz="0.0" izz="1.0"/>
    </inertial>
  </link>
  <joint name="human_base_fixed_joint" type="fixed">
    <origin rpy="0 0 0" xyz="0 0 0"/>
    <parent link="world"/>
    <child link="human_base_link"/>
  </joint>
  <!-- Shoulder joints -->
  <link name="left_shoulder_1_link">
    <inertial>
      <origin rpy="0 0 0" xyz="0 0 0"/>
      <mass value="1"/>
      <inertia ixx="1.0" ixy="0.0" ixz="0.0" iyy="1.0" iyz="0.0" izz="1.0"/>
    </inertial>
  </link>
  <joint name="left_shoulder_1_joint" type="revolute">
    <origin rpy="0 0 0" xyz="0 0.27 1.3"/>
    <axis xyz="0 1 0"/>
    <parent link="human_base_link"/>
    <child link="left_shoulder_1_link"/>
    <limit effort="100" lower="-1.57079632679" upper="0.785398163397" velocity="100"/>
  </joint>
  <link name="left_shoulder_2_link">
    <inertial>
      <origin rpy="0 0 0" xyz="0 0 0"/>
      <mass value="1"/>
      <inertia ixx="1.0" ixy="0.0" ixz="0.0" iyy="1.0" iyz="0.0" izz="1.0"/>
    </inertial>
  </link>
  <joint name="left_shoulder_2_joint" type="revolute">
    <origin rpy="0 0 0" xyz="0 0 0"/>
    <axis xyz="-1 0 0"/>
    <parent link="left_shoulder_1_link"/>
    <child link="left_shoulder_2_link"/>
    <limit effort="100" lower="-1.57079632679" upper="1.57079632679" velocity="100"/>
  </joint>
  <link name="left_shoulder_3_link"/>
  <joint name="left_shoulder_3_joint" type="revolute">
    <origin rpy="0 0 0" xyz="0 0 0"/>
    <axis xyz="0 0 -1"/>
    <parent link="left_shoulder_2_link"/>
    <child link="left_shoulder_3_link"/>
    <limit effort="100" lower="-1.57079632679" upper="1.57079632679" velocity="100"/>
  </joint>
  <!-- Upperarm link -->
  <link name="left_upperarm_link">
    <visual>
      <origin rpy="0 0 0" xyz="0 0 0"/>
      <geometry>
        <cylinder length="0.15" radius="0.04"/>
      </geometry>
      <material name="blue">
        <color rgba="0 0 1 1"/>
      </material>
    </visual>
    <collision>
      <origin rpy="0 0 0" xyz="0 0 0"/>
      <geometry>
        <cylinder length="0.15" radius="0.04"/>
      </geometry>
    </collision>
    <inertial>
      <origin rpy="0 0 0" xyz="0 0 0"/>
      <mass value="1"/>
      <inertia ixx="1.0" ixy="0.0" ixz="0.0" iyy="1.0" iyz="0.0" izz="1.0"/>
    </inertial>
  </link>
  <joint name="left_upperarm_fixed_joint" type="fixed">
    <origin rpy="0 0 0" xyz="0 0 -0.075"/>
    <parent link="left_shoulder_3_link"/>
    <child link="left_upperarm_link"/>
  </joint>
  <!-- Elbow joints -->
  <link name="left_elbow_1_link">
    <inertial>
      <origin rpy="0 0 0" xyz="0 0 0"/>
      <mass value="1"/>
      <inertia ixx="1.0" ixy="0.0" ixz="0.0" iyy="1.0" iyz="0.0" izz="1.0"/>
    </inertial>
  </link>
  <joint name="left_elbow_1_joint" type="revolute">
    <origin rpy="0 0 0" xyz="0 0 -0.075"/>
    <axis xyz="-1 0 0"/>
    <parent link="left_upperarm_link"/>
    <child link="left_elbow_1_link"/>
    <limit effort="100" lower="0.0" upper="2.09439510239" velocity="100"/>
  </joint>
  <link name="left_elbow_2_link">
    <inertial>
      <origin rpy="0 0 0" xyz="0 0 0"/>
      <mass value="1"/>
      <inertia ixx="1.0" ixy="0.0" ixz="0.0" iyy="1.0" iyz="0.0" izz="1.0"/>
    </inertial>
  </link>
  <joint name="left_elbow_2_joint" type="revolute">
    <origin rpy="0 0 0" xyz="0 0 0"/>
    <axis xyz="0 0 -1"/>
    <parent link="left_elbow_1_link"/>
    <child link="left_elbow_2_link"/>
    <limit effort="100" lower="-3.14159265359" upper="3.14159265359" velocity="100"/>
  </joint>
  <!-- Forearm link -->
  <link name="left_forearm_link">
    <visual>
      <origin rpy="0 0 0" xyz="0 0 0"/>
      <geometry>
        <cylinder length="0.2" radius="0.04"/>
      </geometry>
      <material name="red">
        <color rgba="1 0 0 1"/>
      </material>
    </visual>
    <collision>
      <origin rpy="0 0 0" xyz="0 0 0"/>
      <geometry>
        <cylinder length="0.2" radius="0.04"/>
      </geometry>
    </collision>
    <inertial>
      <origin rpy="0 0 0" xyz="0 0 0"/>
      <mass value="1"/>
      <inertia ixx="1.0" ixy="0.0" ixz="0.0" iyy="1.0" iyz="0.0" izz="1.0"/>
    </inertial>
  </link>
  <joint name="left_forearm_fixed_joint" type="fixed">
    <origin rpy="0 0 0" xyz="0 0 -0.1"/>
    <parent link="left_elbow_2_link"/>
    <child link="left_forearm_link"/>
  </joint>
  <!-- Wrist joints -->
  <link name="left_wrist_1_link">
    <inertial>
      <origin rpy="0 0 0" xyz="0 0 0"/>
      <mass value="1"/>
      <inertia ixx="1.0" ixy="0.0" ixz="0.0" iyy="1.0" iyz="0.0" izz="1.0"/>
    </inertial>
  </link>
  <joint name="left_wrist_1_joint" type="revolute">
    <origin rpy="0 0 0" xyz="0 0 -0.1"/>
    <axis xyz="-1 0 0"/>
    <parent link="left_forearm_link"/>
    <child link="left_wrist_1_link"/>
    <limit effort="100" lower="-1.57079632679" upper="1.57079632679" velocity="100"/>
  </joint>
  <link name="left_wrist_2_link">
    <inertial>
      <origin rpy="0 0 0" xyz="0 0 0"/>
      <mass value="1"/>
      <inertia ixx="1.0" ixy="0.0" ixz="0.0" iyy="1.0" iyz="0.0" izz="1.0"/>
    </inertial>
  </link>
  <joint name="left_wrist_2_joint" type="revolute">
    <origin rpy="0 0 0" xyz="0 0 0"/>
    <axis xyz="0 1 0"/>
    <parent link="left_wrist_1_link"/>
    <child link="left_wrist_2_link"/>
    <limit effort="100" lower="-0.785398163397" upper="0.785398163397" velocity="100"/>
  </joint>
  <!-- Hand link -->
  <link name="left_hand_link">
    <visual>
      <origin rpy="0 0 0" xyz="0 0 0"/>
      <geometry>
        <cylinder length="0.12" radius="0.04"/>
      </geometry>
      <material name="green">
        <color rgba="0 1 0 1"/>
      </material>
    </visual>
    <collision>
      <origin rpy="0 0 0" xyz="0 0 0"/>
      <geometry>
        <cylinder length="0.12" radius="0.04"/>
      </geometry>
    </collision>
    <inertial>
      <origin rpy="0 0 0" xyz="0 0 0"/>
      <mass value="1"/>
      <inertia ixx="1.0" ixy="0.0" ixz="0.0" iyy="1.0" iyz="0.0" izz="1.0"/>
    </inertial>
  </link>
  <joint name="left_hand_fixed_joint" type="fixed">
    <origin rpy="0 0 0" xyz="0 0 -0.06"/>
    <parent link="left_wrist_2_link"/>
    <child link="left_hand_link"/>
  </joint>
  <!-- Virtual hand tip -->
  <link name="left_virtual_hand_tip_link"/>
  <joint name="left_hand_tip_fixed_joint" type="fixed">
    <origin rpy="0 0 0" xyz="0 0 -0.06"/>
    <parent link="left_hand_link"/>
    <child link="left_virtual_hand_tip_link"/>
  </joint>
  <!-- Transmission information -->
  <!-- Shoulder joints -->
  <transmission name="left_shoulder_1_trans">
    <type>transmission_interface/SimpleTransmission</type>
    <joint name="left_shoulder_1_joint">
      <hardwareInterface>hardware_interface/PositionJointInterface</hardwareInterface>
    </joint>
    <actuator name="left_shoulder_1_actuator">
      <hardwareInterface>hardware_interface/PositionJointInterface</hardwareInterface>
      <mechanicalReduction>1</mechanicalReduction>
    </actuator>
  </transmission>
  <transmission name="left_shoulder_2_trans">
    <type>transmission_interface/SimpleTransmission</type>
    <joint name="left_shoulder_2_joint">
      <hardwareInterface>hardware_interface/PositionJointInterface</hardwareInterface>
    </joint>
    <actuator name="left_shoulder_2_actuator">
      <hardwareInterface>hardware_interface/PositionJointInterface</hardwareInterface>
      <mechanicalReduction>1</mechanicalReduction>
    </actuator>
  </transmission>
  <transmission name="left_shoulder_3_trans">
    <type>transmission_interface/SimpleTransmission</type>
    <joint name="left_shoulder_3_joint">
      <hardwareInterface>hardware_interface/PositionJointInterface</hardwareInterface>
    </joint>
    <actuator name="left_shoulder_3_actuator">
      <hardwareInterface>hardware_interface/PositionJointInterface</hardwareInterface>
      <mechanicalReduction>1</mechanicalReduction>
    </actuator>
  </transmission>
  <!-- Elbow joints -->
  <transmission name="left_elbow_1_trans">
    <type>transmission_interface/SimpleTransmission</type>
    <joint name="left_elbow_1_joint">
      <hardwareInterface>hardware_interface/PositionJointInterface</hardwareInterface>
    </joint>
    <actuator name="left_elbow_1_actuator">
      <hardwareInterface>hardware_interface/PositionJointInterface</hardwareInterface>
      <mechanicalReduction>1</mechanicalReduction>
    </actuator>
  </transmission>
  <transmission name="left_elbow_2_trans">
    <type>transmission_interface/SimpleTransmission</type>
    <joint name="left_elbow_2_joint">
      <hardwareInterface>hardware_interface/PositionJointInterface</hardwareInterface>
    </joint>
    <actuator name="left_elbow_2_actuator">
      <hardwareInterface>hardware_interface/PositionJointInterface</hardwareInterface>
      <mechanicalReduction>1</mechanicalReduction>
    </actuator>
  </transmission>
  <!-- Wrist joints -->
  <transmission name="left_wrist_1_trans">
    <type>transmission_interface/SimpleTransmission</type>
    <joint name="left_wrist_1_joint">
      <hardwareInterface>hardware_interface/PositionJointInterface</hardwareInterface>
    </joint>
    <actuator name="left_wrist_1_actuator">
      <hardwareInterface>hardware_interface/PositionJointInterface</hardwareInterface>
      <mechanicalReduction>1</mechanicalReduction>
    </actuator>
  </transmission>
  <transmission name="left_wrist_2_trans">
    <type>transmission_interface/SimpleTransmission</type>
    <joint name="left_wrist_2_joint">
      <hardwareInterface>hardware_interface/PositionJointInterface</hardwareInterface>
    </joint>
    <actuator name="left_wrist_2_actuator">
      <hardwareInterface>hardware_interface/PositionJointInterface</hardwareInterface>
      <mechanicalReduction>1</mechanicalReduction>
    </actuator>
  </transmission>
  <!-- Shoulder joints -->
  <link name="right_shoulder_1_link">
    <inertial>
      <origin rpy="0 0 0" xyz="0 0 0"/>
      <mass value="1"/>
      <inertia ixx="1.0" ixy="0.0" ixz="0.0" iyy="1.0" iyz="0.0" izz="1.0"/>
    </inertial>
  </link>
  <joint name="right_shoulder_1_joint" type="revolute">
    <origin rpy="0 0 0" xyz="0 -0.27 1.3"/>
    <axis xyz="0 1 0"/>
    <parent link="human_base_link"/>
    <child link="right_shoulder_1_link"/>
    <limit effort="100" lower="-1.57079632679" upper="0.785398163397" velocity="100"/>
  </joint>
  <link name="right_shoulder_2_link">
    <inertial>
      <origin rpy="0 0 0" xyz="0 0 0"/>
      <mass value="1"/>
      <inertia ixx="1.0" ixy="0.0" ixz="0.0" iyy="1.0" iyz="0.0" izz="1.0"/>
    </inertial>
  </link>
  <joint name="right_shoulder_2_joint" type="revolute">
    <origin rpy="0 0 0" xyz="0 0 0"/>
    <axis xyz="1 0 0"/>
    <parent link="right_shoulder_1_link"/>
    <child link="right_shoulder_2_link"/>
    <limit effort="100" lower="-1.57079632679" upper="1.57079632679" velocity="100"/>
  </joint>
  <link name="right_shoulder_3_link"/>
  <joint name="right_shoulder_3_joint" type="revolute">
    <origin rpy="0 0 0" xyz="0 0 0"/>
    <axis xyz="0 0 1"/>
    <parent link="right_shoulder_2_link"/>
    <child link="right_shoulder_3_link"/>
    <limit effort="100" lower="-1.57079632679" upper="1.57079632679" velocity="100"/>
  </joint>
  <!-- Upperarm link -->
  <link name="right_upperarm_link">
    <visual>
      <origin rpy="0 0 0" xyz="0 0 0"/>
      <geometry>
        <cylinder length="0.15" radius="0.04"/>
      </geometry>
      <material name="blue">
        <color rgba="0 0 1 1"/>
      </material>
    </visual>
    <collision>
      <origin rpy="0 0 0" xyz="0 0 0"/>
      <geometry>
        <cylinder length="0.15" radius="0.04"/>
      </geometry>
    </collision>
    <inertial>
      <origin rpy="0 0 0" xyz="0 0 0"/>
      <mass value="1"/>
      <inertia ixx="1.0" ixy="0.0" ixz="0.0" iyy="1.0" iyz="0.0" izz="1.0"/>
    </inertial>
  </link>
  <joint name="right_upperarm_fixed_joint" type="fixed">
    <origin rpy="0 0 0" xyz="0 0 -0.075"/>
    <parent link="right_shoulder_3_link"/>
    <child link="right_upperarm_link"/>
  </joint>
  <!-- Elbow joints -->
  <link name="right_elbow_1_link">
    <inertial>
      <origin rpy="0 0 0" xyz="0 0 0"/>
      <mass value="1"/>
      <inertia ixx="1.0" ixy="0.0" ixz="0.0" iyy="1.0" iyz="0.0" izz="1.0"/>
    </inertial>
  </link>
  <joint name="right_elbow_1_joint" type="revolute">
    <origin rpy="0 0 0" xyz="0 0 -0.075"/>
    <axis xyz="1 0 0"/>
    <parent link="right_upperarm_link"/>
    <child link="right_elbow_1_link"/>
    <limit effort="100" lower="0.0" upper="2.09439510239" velocity="100"/>
  </joint>
  <link name="right_elbow_2_link">
    <inertial>
      <origin rpy="0 0 0" xyz="0 0 0"/>
      <mass value="1"/>
      <inertia ixx="1.0" ixy="0.0" ixz="0.0" iyy="1.0" iyz="0.0" izz="1.0"/>
    </inertial>
  </link>
  <joint name="right_elbow_2_joint" type="revolute">
    <origin rpy="0 0 0" xyz="0 0 0"/>
    <axis xyz="0 0 1"/>
    <parent link="right_elbow_1_link"/>
    <child link="right_elbow_2_link"/>
    <limit effort="100" lower="-3.14159265359" upper="3.14159265359" velocity="100"/>
  </joint>
  <!-- Forearm link -->
  <link name="right_forearm_link">
    <visual>
      <origin rpy="0 0 0" xyz="0 0 0"/>
      <geometry>
        <cylinder length="0.2" radius="0.04"/>
      </geometry>
      <material name="red">
        <color rgba="1 0 0 1"/>
      </material>
    </visual>
    <collision>
      <origin rpy="0 0 0" xyz="0 0 0"/>
      <geometry>
        <cylinder length="0.2" radius="0.04"/>
      </geometry>
    </collision>
    <inertial>
      <origin rpy="0 0 0" xyz="0 0 0"/>
      <mass value="1"/>
      <inertia ixx="1.0" ixy="0.0" ixz="0.0" iyy="1.0" iyz="0.0" izz="1.0"/>
    </inertial>
  </link>
  <joint name="right_forearm_fixed_joint" type="fixed">
    <origin rpy="0 0 0" xyz="0 0 -0.1"/>
    <parent link="right_elbow_2_link"/>
    <child link="right_forearm_link"/>
  </joint>
  <!-- Wrist joints -->
  <link name="right_wrist_1_link">
    <inertial>
      <origin rpy="0 0 0" xyz="0 0 0"/>
      <mass value="1"/>
      <inertia ixx="1.0" ixy="0.0" ixz="0.0" iyy="1.0" iyz="0.0" izz="1.0"/>
    </inertial>
  </link>
  <joint name="right_wrist_1_joint" type="revolute">
    <origin rpy="0 0 0" xyz="0 0 -0.1"/>
    <axis xyz="1 0 0"/>
    <parent link="right_forearm_link"/>
    <child link="right_wrist_1_link"/>
    <limit effort="100" lower="-1.57079632679" upper="1.57079632679" velocity="100"/>
  </joint>
  <link name="right_wrist_2_link">
    <inertial>
      <origin rpy="0 0 0" xyz="0 0 0"/>
      <mass value="1"/>
      <inertia ixx="1.0" ixy="0.0" ixz="0.0" iyy="1.0" iyz="0.0" izz="1.0"/>
    </inertial>
  </link>
  <joint name="right_wrist_2_joint" type="revolute">
    <origin rpy="0 0 0" xyz="0 0 0"/>
    <axis xyz="0 1 0"/>
    <parent link="right_wrist_1_link"/>
    <child link="right_wrist_2_link"/>
    <limit effort="100" lower="-0.785398163397" upper="0.785398163397" velocity="100"/>
  </joint>
  <!-- Hand link -->
  <link name="right_hand_link">
    <visual>
      <origin rpy="0 0 0" xyz="0 0 0"/>
      <geometry>
        <cylinder length="0.12" radius="0.04"/>
      </geometry>
      <material name="green">
        <color rgba="0 1 0 1"/>
      </material>
    </visual>
    <collision>
      <origin rpy="0 0 0" xyz="0 0 0"/>
      <geometry>
        <cylinder length="0.12" radius="0.04"/>
      </geometry>
    </collision>
    <inertial>
      <origin rpy="0 0 0" xyz="0 0 0"/>
      <mass value="1"/>
      <inertia ixx="1.0" ixy="0.0" ixz="0.0" iyy="1.0" iyz="0.0" izz="1.0"/>
    </inertial>
  </link>
  <joint name="right_hand_fixed_joint" type="fixed">
    <origin rpy="0 0 0" xyz="0 0 -0.06"/>
    <parent link="right_wrist_2_link"/>
    <child link="right_hand_link"/>
  </joint>
  <!-- Virtual hand tip -->
  <link name="right_virtual_hand_tip_link"/>
  <joint name="right_hand_tip_fixed_joint" type="fixed">
    <origin rpy="0 0 0" xyz="0 0 -0.06"/>
    <parent link="right_hand_link"/>
    <child link="right_virtual_hand_tip_link"/>
  </joint>
  <!-- Transmission information -->
  <!-- Shoulder joints -->
  <transmission name="right_shoulder_1_trans">
    <type>transmission_interface/SimpleTransmission</type>
    <joint name="right_shoulder_1_joint">
      <hardwareInterface>hardware_interface/PositionJointInterface</hardwareInterface>
    </joint>
    <actuator name="right_shoulder_1_actuator">
      <hardwareInterface>hardware_interface/PositionJointInterface</hardwareInterface>
      <mechanicalReduction>1</mechanicalReduction>
    </actuator>
  </transmission>
  <transmission name="right_shoulder_2_trans">
    <type>transmission_interface/SimpleTransmission</type>
    <joint name="right_shoulder_2_joint">
      <hardwareInterface>hardware_interface/PositionJointInterface</hardwareInterface>
    </joint>
    <actuator name="right_shoulder_2_actuator">
      <hardwareInterface>hardware_interface/PositionJointInterface</hardwareInterface>
      <mechanicalReduction>1</mechanicalReduction>
    </actuator>
  </transmission>
  <transmission name="right_shoulder_3_trans">
    <type>transmission_interface/SimpleTransmission</type>
    <joint name="right_shoulder_3_joint">
      <hardwareInterface>hardware_interface/PositionJointInterface</hardwareInterface>
    </joint>
    <actuator name="right_shoulder_3_actuator">
      <hardwareInterface>hardware_interface/PositionJointInterface</hardwareInterface>
      <mechanicalReduction>1</mechanicalReduction>
    </actuator>
  </transmission>
  <!-- Elbow joints -->
  <transmission name="right_elbow_1_trans">
    <type>transmission_interface/SimpleTransmission</type>
    <joint name="right_elbow_1_joint">
      <hardwareInterface>hardware_interface/PositionJointInterface</hardwareInterface>
    </joint>
    <actuator name="right_elbow_1_actuator">
      <hardwareInterface>hardware_interface/PositionJointInterface</hardwareInterface>
      <mechanicalReduction>1</mechanicalReduction>
    </actuator>
  </transmission>
  <transmission name="right_elbow_2_trans">
    <type>transmission_interface/SimpleTransmission</type>
    <joint name="right_elbow_2_joint">
      <hardwareInterface>hardware_interface/PositionJointInterface</hardwareInterface>
    </joint>
    <actuator name="right_elbow_2_actuator">
      <hardwareInterface>hardware_interface/PositionJointInterface</hardwareInterface>
      <mechanicalReduction>1</mechanicalReduction>
    </actuator>
  </transmission>
  <!-- Wrist joints -->
  <transmission name="right_wrist_1_trans">
    <type>transmission_interface/SimpleTransmission</type>
    <joint name="right_wrist_1_joint">
      <hardwareInterface>hardware_interface/PositionJointInterface</hardwareInterface>
    </joint>
    <actuator name="right_wrist_1_actuator">
      <hardwareInterface>hardware_interface/PositionJointInterface</hardwareInterface>
      <mechanicalReduction>1</mechanicalReduction>
    </actuator>
  </transmission>
  <transmission name="right_wrist_2_trans">
    <type>transmission_interface/SimpleTransmission</type>
    <joint name="right_wrist_2_joint">
      <hardwareInterface>hardware_interface/PositionJointInterface</hardwareInterface>
    </joint>
    <actuator name="right_wrist_2_actuator">
      <hardwareInterface>hardware_interface/PositionJointInterface</hardwareInterface>
      <mechanicalReduction>1</mechanicalReduction>
    </actuator>
  </transmission>
</robot>

